Workbook

Sheet week1
A1: time(minute) | B1: UV irradiance (mw/cm2) | C1: Cl20 (mgCl2/L) | D1: pH | E1: Phosphate buffer (mM) | F1: dioxane0 (micromol/L) | G1: dioxane0 (microgram/L) | H1: Cl2free (mgCl2/L) | I1: dioxane (microgram/L) | J1: dioxane C/C0
A2: 0 | B2: 0.1 | C2: 10 | D2: 7 | E2: 2 | F2: =1 -> 1 | G2: =F2*88.11 -> 88.11 | I2: =G2 -> 88.11 | J2: =I2/$G$2 -> 1
A3: 5 | B3: 0.1 | C3: 10 | D3: 7 | E3: 2 | F3: =1 -> 1 | G3: =F3*88.11 -> 88.11 | I3: 114.477 | J3: =I3/$G$2 -> 1.2992509
A4: 20 | B4: 0.1 | C4: 10 | D4: 7 | E4: 2 | F4: =1 -> 1 | G4: =F4*88.11 -> 88.11 | I4: 94.03 | J4: =I4/$G$2 -> 1.0671887
A5: 35 | B5: 0.1 | C5: 10 | D5: 7 | E5: 2 | F5: =1 -> 1 | G5: =F5*88.11 -> 88.11 | H5: 2.8 | I5: 87.72 | J5: =I5/$G$2 -> 0.99557371
A6: 0 | B6: 0 | C6: 10 | D6: 7 | E6: 2 | F6: =1 -> 1 | G6: =F6*88.11 -> 88.11 | I6: =G6 -> 88.11 | J6: =I6/$G$2 -> 1
A7: 5 | B7: 0 | C7: 10 | D7: 7 | E7: 2 | F7: =1 -> 1 | G7: =F7*88.11 -> 88.11 | I7: 117.69 | J7: =I7/$G$2 -> 1.3357167
A8: 20 | B8: 0 | C8: 10 | D8: 7 | E8: 2 | F8: =1 -> 1 | G8: =F8*88.11 -> 88.11 | I8: 110.97 | J8: =I8/$G$2 -> 1.2594484
A9: 35 | B9: 0 | C9: 10 | D9: 7 | E9: 2 | F9: =1 -> 1 | G9: =F9*88.11 -> 88.11 | H9: 7.6 | I9: 111.81 | J9: =I9/$G$2 -> 1.268982

Sheet week2
A1: time(minute) | B1: UV | C1: Cl20 (mgCl2/L) | D1: pH | E1: Phosphate buffer (mM) | F1: dioxane0 (micromol/L) | G1: dioxane0 (microgram/L) | H1: Cl2free (mgCl2/L) | I1: dioxane (microgram/L) | J1: dioxane C/C0
A2: 0 | B2: 0.1 | C2: 10 | D2: 7.1 | E2: 2 | F2: 1 | G2: =F2*88.11 -> 88.11 | H2: 9.6 | I2: =G2 -> 88.11 | J2: =I2/$G$2 -> 1
A3: 10 | B3: 0.1 | C3: 10 | D3: 7.1 | E3: 2 | F3: 1 | G3: =F3*88.11 -> 88.11 | H3: 7.7 | I3: 83.9864 | J3: =I3/$G$2 -> 0.95319941
A4: 20 | B4: 0.1 | C4: 10 | D4: 7.1 | E4: 2 | F4: 1 | G4: =F4*88.11 -> 88.11 | H4: 6.8 | I4: 62.1914 | J4: =I4/$G$2 -> 0.70583816
A5: 30 | B5: 0.1 | C5: 10 | D5: 7.1 | E5: 2 | F5: 1 | G5: =F5*88.11 -> 88.11 | H5: 6.4 | I5: 84.9368 | J5: =I5/$G$2 -> 0.96398593
A6: 0 | B6: 0 | C6: 10 | D6: 7.1 | E6: 2 | F6: 1 | G6: =F6*88.11 -> 88.11 | H6: 9.5 | I6: =G6 -> 88.11 | J6: =I6/$G$2 -> 1
A7: 10 | B7: 0 | C7: 10 | D7: 7.1 | E7: 2 | F7: 1 | G7: =F7*88.11 -> 88.11 | H7: 8.2 | I7: 83.107 | J7: =I7/$G$2 -> 0.9432187
A8: 20 | B8: 0 | C8: 10 | D8: 7.1 | E8: 2 | F8: 1 | G8: =F8*88.11 -> 88.11 | H8: 6.3 | I8: 84.4459 | J8: =I8/$G$2 -> 0.95841448
A9: 30 | B9: 0 | C9: 10 | D9: 7.1 | E9: 2 | F9: 1 | G9: =F9*88.11 -> 88.11 | H9: 8.6 | I9: 64.3748 | J9: =I9/$G$2 -> 0.73061855

Sheet week2-2
A1: replicate | B1: time(minute) | C1: UV | D1: Cl20 (mgCl2/L) | E1: pH | F1: Phosphate buffer (mM) | G1: dioxane0 (micromol/L) | H1: dioxane0 (microgram/L) | I1: Cl2free dilution x5 (mgCl2/L) | J1: Cl2free (mgCl2/L) | K1: Cl2 C/C0 | L1: dioxane (microgram/L) | M1: dioxane C/C0
A2: 1 | B2: 0 | C2: 0.1 | D2: 10 | E2: 7.1 | F2: 2 | G2: 1 | H2: =AVERAGE(89,85.9) -> 87.45 | I2: 1.97 | J2: =I2*5 -> 9.85 | K2: =J2/10 -> 0.985 | L2: =$H$2 -> 87.45 | M2: =L2/$H$2 -> 1
A3: 1 | B3: 4 | C3: 0.1 | D3: 10 | E3: 7.1 | F3: 2 | G3: 1 | H3: =AVERAGE(89,85.9) -> 87.45 | I3: 1.73 | J3: =I3*5 -> 8.65 | K3: =J3/10 -> 0.865
A4: 1 | B4: 16 | C4: 0.1 | D4: 10 | E4: 7.1 | F4: 2 | G4: 1 | H4: =AVERAGE(89,85.9) -> 87.45 | I4: 1.72 | J4: =I4*5 -> 8.6 | K4: =J4/10 -> 0.86 | L4: 87.72 | M4: =L4/$H$2 -> 1.0030875
A5: 1 | B5: 25 | C5: 0.1 | D5: 10 | E5: 7.1 | F5: 2 | G5: 1 | H5: =AVERAGE(89,85.9) -> 87.45 | I5: =AVERAGE(1.7,1.72) -> 1.71 | J5: =I5*5 -> 8.55 | K5: =J5/10 -> 0.855 | L5: 59 | M5: =L5/$H$2 -> 0.67467124
A6: 1 | B6: 35 | C6: 0.1 | D6: 10 | E6: 7.1 | F6: 2 | G6: 1 | H6: =AVERAGE(89,85.9) -> 87.45 | I6: =1.47 -> 1.47 | J6: =I6*5 -> 7.35 | K6: =J6/10 -> 0.735 | L6: 48.6 | M6: =L6/$H$2 -> 0.55574614
A7: 2 | B7: 0 | C7: 0.1 | D7: 10 | E7: 7.1 | F7: 2 | G7: 1 | H7: =AVERAGE(89,85.9) -> 87.45 | I7: 1.97 | J7: =I7*5 -> 9.85 | K7: =J7/10 -> 0.985 | L7: =$H$2 -> 87.45 | M7: =L7/$H$2 -> 1
A8: 2 | B8: 4 | C8: 0.1 | D8: 10 | E8: 7.1 | F8: 2 | G8: 1 | H8: =AVERAGE(89,85.9) -> 87.45 | I8: 1.73 | J8: =I8*5 -> 8.65 | K8: =J8/10 -> 0.865
A9: 2 | B9: 16 | C9: 0.1 | D9: 10 | E9: 7.1 | F9: 2 | G9: 1 | H9: =AVERAGE(89,85.9) -> 87.45 | I9: 1.72 | J9: =I9*5 -> 8.6 | K9: =J9/10 -> 0.86 | L9: 74 | M9: =L9/$H$2 -> 0.84619783
A10: 2 | B10: 25 | C10: 0.1 | D10: 10 | E10: 7.1 | F10: 2 | G10: 1 | H10: =AVERAGE(89,85.9) -> 87.45 | I10: 1.72 | J10: =I10*5 -> 8.6 | K10: =J10/10 -> 0.86 | L10: 70 | M10: =L10/$H$2 -> 0.8004574
A11: 2 | B11: 35 | C11: 0.1 | D11: 10 | E11: 7.1 | F11: 2 | G11: 1 | H11: =AVERAGE(89,85.9) -> 87.45 | I11: =1.47 -> 1.47 | J11: =I11*5 -> 7.35 | K11: =J11/10 -> 0.735 | L11: 63 | M11: =L11/$H$2 -> 0.72041166
A12: 1 | B12: 0 | C12: 0 | D12: 10 | E12: 7.1 | F12: 2 | G12: 1 | H12: =AVERAGE(89,85.9) -> 87.45 | I12: 1.97 | J12: =I12*5 -> 9.85 | K12: =J12/10 -> 0.985 | L12: =$H$2 -> 87.45 | M12: =L12/$H$2 -> 1
A13: 1 | B13: 4 | C13: 0 | D13: 10 | E13: 7.1 | F13: 2 | G13: 1 | H13: =AVERAGE(89,85.9) -> 87.45 | I13: 1.92 | J13: =I13*5 -> 9.6 | K13: =J13/10 -> 0.96
A14: 1 | B14: 16 | C14: 0 | D14: 10 | E14: 7.1 | F14: 2 | G14: 1 | H14: =AVERAGE(89,85.9) -> 87.45 | I14: 1.89 | J14: =I14*5 -> 9.45 | K14: =J14/10 -> 0.945 | L14: 93.14 | M14: =L14/$H$2 -> 1.0650658
A15: 1 | B15: 25 | C15: 0 | D15: 10 | E15: 7.1 | F15: 2 | G15: 1 | H15: =AVERAGE(89,85.9) -> 87.45 | I15: =AVERAGE(1.91,1.89) -> 1.9 | J15: =I15*5 -> 9.5 | K15: =J15/10 -> 0.95 | L15: 79 | M15: =L15/$H$2 -> 0.90337336
A16: 1 | B16: 35 | C16: 0 | D16: 10 | E16: 7.1 | F16: 2 | G16: 1 | H16: =AVERAGE(89,85.9) -> 87.45 | I16: =AVERAGE(1.97,1.87) -> 1.92 | J16: =I16*5 -> 9.6 | K16: =J16/10 -> 0.96 | L16: 65 | M16: =L16/$H$2 -> 0.74328188
A17: 2 | B17: 0 | C17: 0 | D17: 10 | E17: 7.1 | F17: 2 | G17: 1 | H17: =AVERAGE(89,85.9) -> 87.45 | I17: 1.97 | J17: =I17*5 -> 9.85 | K17: =J17/10 -> 0.985 | L17: =$H$2 -> 87.45 | M17: =L17/$H$2 -> 1
A18: 2 | B18: 4 | C18: 0 | D18: 10 | E18: 7.1 | F18: 2 | G18: 1 | H18: =AVERAGE(89,85.9) -> 87.45 | I18: 1.92 | J18: =I18*5 -> 9.6 | K18: =J18/10 -> 0.96
A19: 2 | B19: 16 | C19: 0 | D19: 10 | E19: 7.1 | F19: 2 | G19: 1 | H19: =AVERAGE(89,85.9) -> 87.45 | I19: 1.89 | J19: =I19*5 -> 9.45 | K19: =J19/10 -> 0.945 | L19: 74.3 | M19: =L19/$H$2 -> 0.84962836
A20: 2 | B20: 25 | C20: 0 | D20: 10 | E20: 7.1 | F20: 2 | G20: 1 | H20: =AVERAGE(89,85.9) -> 87.45 | I20: =AVERAGE(1.91,1.89) -> 1.9 | J20: =I20*5 -> 9.5 | K20: =J20/10 -> 0.95 | L20: 75.9 | M20: =L20/$H$2 -> 0.86792453
A21: 2 | B21: 35 | C21: 0 | D21: 10 | E21: 7.1 | F21: 2 | G21: 1 | H21: =AVERAGE(89,85.9) -> 87.45 | I21: =AVERAGE(1.97,1.87) -> 1.92 | J21: =I21*5 -> 9.6 | K21: =J21/10 -> 0.96 | L21: 64.6 | M21: =L21/$H$2 -> 0.73870783

Sheet week3
A1: replicate | B1: time(minute) | C1: UV | D1: Cl20 (mgCl2/L) | E1: pH | F1: Phosphate buffer (mM) | G1: dioxane0 (micromol/L) | H1: dioxane0 (microgram/L) | I1: Cl2free dilution x5 (mgCl2/L) | J1: Cl2free (mgCl2/L) | K1: Cl2 C/C0 | L1: dioxane (microgram/L) | M1: dioxane C/C0
A2: 1 | B2: 0 | C2: 0.1 | D2: 10 | E2: 5.5 | F2: 2 | G2: 1 | H2: =AVERAGE(6600,6790) -> 6695 | I2: 1.95 | J2: =I2*5 -> 9.75 | K2: =J2/10 -> 0.975 | L2: =$H$2 -> 6695 | M2: =L2/$H$2 -> 1
A3: 1 | B3: 10 | C3: 0.1 | D3: 10 | E3: 5.5 | F3: 2 | G3: 1 | H3: =AVERAGE(6600,6790) -> 6695 | I3: 1.16 | J3: =I3*5 -> 5.8 | K3: =J3/10 -> 0.58 | L3: 247 | M3: =L3/$H$2 -> 0.036893204
A4: 1 | B4: 20 | C4: 0.1 | D4: 10 | E4: 5.5 | F4: 2 | G4: 1 | H4: =AVERAGE(6600,6790) -> 6695 | I4: 1.11 | J4: =I4*5 -> 5.55 | K4: =J4/10 -> 0.555
A5: 1 | B5: 30 | C5: 0.1 | D5: 10 | E5: 5.5 | F5: 2 | G5: 1 | H5: =AVERAGE(6600,6790) -> 6695 | I5: 0.86 | J5: =I5*5 -> 4.3 | K5: =J5/10 -> 0.43 | L5: 50 | M5: =L5/$H$2 -> 0.0074682599
A6: 2 | B6: 0 | C6: 0.1 | D6: 10 | E6: 5.5 | F6: 2 | G6: 1 | H6: =AVERAGE(6600,6790) -> 6695 | I6: 1.95 | J6: =I6*5 -> 9.75 | K6: =J6/10 -> 0.975 | L6: =$H$2 -> 6695 | M6: =L6/$H$2 -> 1
A7: 2 | B7: 10 | C7: 0.1 | D7: 10 | E7: 5.5 | F7: 2 | G7: 1 | H7: =AVERAGE(6600,6790) -> 6695 | I7: 1.16 | J7: =I7*5 -> 5.8 | K7: =J7/10 -> 0.58 | L7: 271 | M7: =L7/$H$2 -> 0.040477969
A8: 2 | B8: 20 | C8: 0.1 | D8: 10 | E8: 5.5 | F8: 2 | G8: 1 | H8: =AVERAGE(6600,6790) -> 6695 | I8: 1.11 | J8: =I8*5 -> 5.55 | K8: =J8/10 -> 0.555
A9: 2 | B9: 30 | C9: 0.1 | D9: 10 | E9: 5.5 | F9: 2 | G9: 1 | H9: =AVERAGE(6600,6790) -> 6695 | I9: 0.86 | J9: =I9*5 -> 4.3 | K9: =J9/10 -> 0.43 | L9: 69 | M9: =L9/$H$2 -> 0.010306199
A10: 1 | B10: 0 | C10: 0 | D10: 10 | E10: 5.5 | F10: 2 | G10: 1 | H10: =AVERAGE(6600,6790) -> 6695 | I10: 1.95 | J10: =I10*5 -> 9.75 | K10: =J10/10 -> 0.975 | L10: =$H$2 -> 6695 | M10: =L10/$H$2 -> 1
A11: 1 | B11: 10 | C11: 0 | D11: 10 | E11: 5.5 | F11: 2 | G11: 1 | H11: =AVERAGE(6600,6790) -> 6695 | I11: 1.81 | J11: =I11*5 -> 9.05 | K11: =J11/10 -> 0.905 | L11: 3342 | M11: =L11/$H$2 -> 0.49917849
A12: 1 | B12: 20 | C12: 0 | D12: 10 | E12: 5.5 | F12: 2 | G12: 1 | H12: =AVERAGE(6600,6790) -> 6695 | I12: 1.78 | J12: =I12*5 -> 8.9 | K12: =J12/10 -> 0.89
A13: 1 | B13: 30 | C13: 0 | D13: 10 | E13: 5.5 | F13: 2 | G13: 1 | H13: =AVERAGE(6600,6790) -> 6695 | I13: 1.77 | J13: =I13*5 -> 8.85 | K13: =J13/10 -> 0.885 | L13: 4976 | M13: =L13/$H$2 -> 0.74324122
A14: 2 | B14: 0 | C14: 0 | D14: 10 | E14: 5.5 | F14: 2 | G14: 1 | H14: =AVERAGE(6600,6790) -> 6695 | I14: 1.95 | J14: =I14*5 -> 9.75 | K14: =J14/10 -> 0.975 | L14: =$H$2 -> 6695 | M14: =L14/$H$2 -> 1
A15: 2 | B15: 10 | C15: 0 | D15: 10 | E15: 5.5 | F15: 2 | G15: 1 | H15: =AVERAGE(6600,6790) -> 6695 | I15: 1.81 | J15: =I15*5 -> 9.05 | K15: =J15/10 -> 0.905 | L15: 3360 | M15: =L15/$H$2 -> 0.50186706
A16: 2 | B16: 20 | C16: 0 | D16: 10 | E16: 5.5 | F16: 2 | G16: 1 | H16: =AVERAGE(6600,6790) -> 6695 | I16: 1.81 | J16: =I16*5 -> 9.05 | K16: =J16/10 -> 0.905
A17: 2 | B17: 30 | C17: 0 | D17: 10 | E17: 5.5 | F17: 2 | G17: 1 | H17: =AVERAGE(6600,6790) -> 6695 | I17: 1.77 | J17: =I17*5 -> 8.85 | K17: =J17/10 -> 0.885 | L17: 3319 | M17: =L17/$H$2 -> 0.49574309

Sheet week3-2
A1: replicate | B1: time(minute) | C1: UV | D1: Cl20 (mgCl2/L) | E1: pH | F1: Phosphate buffer (mM) | G1: dioxane0 (micromol/L) | H1: dioxane0 (microgram/L) | I1: Cl2free dilution x5 (mgCl2/L) | J1: Cl2free (mgCl2/L) | K1: Cl2 C/C0 | L1: dioxane (microgram/L) | M1: dioxane C/C0
A2: 1 | B2: 0 | C2: 0.1 | D2: 10 | E2: 5.7 | F2: 2 | I2: 1.57 | J2: =I2*5 -> 7.85 | K2: =J2/$J$2 -> 1 | M2: =L2/$H$2 -> #DIV/0!
A3: 1 | B3: 5 | C3: 0.1 | D3: 10 | E3: 5.7 | F3: 2 | I3: 1.05 | J3: =I3*5 -> 5.25 | K3: =J3/$J$2 -> 0.66878981 | M3: =L3/$H$2 -> #DIV/0!
A4: 1 | B4: 10 | C4: 0.1 | D4: 10 | E4: 5.7 | F4: 2 | I4: 0.97 | J4: =I4*5 -> 4.85 | K4: =J4/$J$2 -> 0.61783439
A5: 1 | B5: 15 | C5: 0.1 | D5: 10 | E5: 5.7 | F5: 2 | I5: 0.89 | J5: =I5*5 -> 4.45 | K5: =J5/$J$2 -> 0.56687898 | M5: =L5/$H$2 -> #DIV/0!
A6: 2 | B6: 20 | C6: 0.1 | D6: 10 | E6: 5.7 | F6: 2 | I6: 0.8 | J6: =I6*5 -> 4 | K6: =J6/$J$2 -> 0.50955414 | M6: =L6/$H$2 -> #DIV/0!
A7: 2 | B7: 25 | C7: 0.1 | D7: 10 | E7: 5.7 | F7: 2 | I7: 0.72 | J7: =I7*5 -> 3.6 | K7: =J7/$J$2 -> 0.45859873 | M7: =L7/$H$2 -> #DIV/0!
A8: 2 | B8: 30 | C8: 0.1 | D8: 10 | E8: 5.7 | F8: 2 | I8: 0.65 | J8: =I8*5 -> 3.25 | K8: =J8/$J$2 -> 0.41401274
A9: 1 | B9: 0 | C9: 0 | D9: 10 | E9: 5.7 | F9: 2 | I9: 1.57 | J9: =I9*5 -> 7.85 | K9: =J9/$J$2 -> 1 | M9: =L9/$H$2 -> #DIV/0!
A10: 1 | B10: 5 | C10: 0 | D10: 10 | E10: 5.7 | F10: 2 | I10: 1.53 | J10: =I10*5 -> 7.65 | K10: =J10/$J$2 -> 0.97452229 | M10: =L10/$H$2 -> #DIV/0!
A11: 1 | B11: 10 | C11: 0 | D11: 10 | E11: 5.7 | F11: 2 | I11: 1.54 | J11: =I11*5 -> 7.7 | K11: =J11/$J$2 -> 0.98089172
A12: 1 | B12: 15 | C12: 0 | D12: 10 | E12: 5.7 | F12: 2 | I12: 1.52 | J12: =I12*5 -> 7.6 | K12: =J12/$J$2 -> 0.96815287 | M12: =L12/$H$2 -> #DIV/0!
A13: 2 | B13: 20 | C13: 0 | D13: 10 | E13: 5.7 | F13: 2 | I13: 1.53 | J13: =I13*5 -> 7.65 | K13: =J13/$J$2 -> 0.97452229 | M13: =L13/$H$2 -> #DIV/0!
A14: 2 | B14: 25 | C14: 0 | D14: 10 | E14: 5.7 | F14: 2 | I14: 1.56 | J14: =I14*5 -> 7.8 | K14: =J14/$J$2 -> 0.99363057 | M14: =L14/$H$2 -> #DIV/0!
A15: 2 | B15: 30 | C15: 0 | D15: 10 | E15: 5.7 | F15: 2 | I15: 1.56 | J15: =I15*5 -> 7.8 | K15: =J15/$J$2 -> 0.99363057

Sheet week4reox
A1: Test number | B1: replicate | C1: time(minute) | D1: UV | E1: Cl20 (mgCl2/L) | F1: pH | G1: Phosphate buffer (mM) | H1: dioxane0 (micromol/L) | I1: dioxane0 (microgram/L) | J1: Cl2free dilution x5 (mgCl2/L) | K1: Cl2free (mgCl2/L) | L1: Cl2free C/C0 | M1: dioxane (microgram/L) | N1: dioxane C/C0
A2: 0 | B2: 1 | C2: 0 | D2: 1 | E2: =1.6*5 -> 8 | F2: 8 | G2: 0 | J2: 1.6 | K2: =J2*5 -> 8 | L2: =K2/$K$2 -> 1
A3: 0 | B3: 1 | C3: 0.5 | D3: 1 | E3: =1.6*5 -> 8 | F3: 8 | G3: 0 | J3: 1.47 | K3: =J3*5 -> 7.35 | L3: =K3/$K$2 -> 0.91875
A4: 0 | B4: 1 | C4: 1 | D4: 1 | E4: =1.6*5 -> 8 | F4: 8 | G4: 0 | J4: 1.52 | K4: =J4*5 -> 7.6 | L4: =K4/$K$2 -> 0.95
A5: 0 | B5: 1 | C5: 5 | D5: 1 | E5: =1.6*5 -> 8 | F5: 8 | G5: 0 | J5: 0.56 | K5: =J5*5 -> 2.8 | L5: =K5/$K$2 -> 0.35
A6: 0 | B6: 2 | C6: 7 | D6: 1 | E6: =1.6*5 -> 8 | F6: 8 | G6: 0 | J6: 0.26 | K6: =J6*5 -> 1.3 | L6: =K6/$K$2 -> 0.1625
A7: 0 | B7: 1 | C7: 9 | D7: 1 | E7: =1.6*5 -> 8 | F7: 8 | G7: 0 | J7: 0.12 | K7: =J7*5 -> 0.6 | L7: =K7/$K$2 -> 0.075
A8: 1 | B8: 2 | C8: 0 | D8: 1 | E8: 8 | F8: 5.5 | G8: 2 | K8: 8.1 | L8: =K8/$K$8 -> 1
A9: 1 | B9: 2 | C9: 2 | D9: 1 | E9: 8 | F9: 5.5 | G9: 2 | K9: 5.4 | L9: =K9/$K$8 -> 0.66666667
A10: 1 | B10: 2 | C10: 4 | D10: 1 | E10: 8 | F10: 5.5 | G10: 2 | K10: 3 | L10: =K10/$K$8 -> 0.37037037
A11: 1 | B11: 2 | C11: 6 | D11: 1 | E11: 8 | F11: 5.5 | G11: 2 | K11: 1.5 | L11: =K11/$K$8 -> 0.18518519
A12: 1 | B12: 2 | C12: 8 | D12: 1 | E12: 8 | F12: 5.5 | G12: 2 | K12: 0.7 | L12: =K12/$K$8 -> 0.086419753
A13: 1 | B13: 2 | C13: 10 | D13: 1 | E13: 8 | F13: 5.5 | G13: 2 | K13: 0.25 | L13: =K13/$K$8 -> 0.030864198
A14: 2 | B14: 1 | C14: 0 | D14: 1 | E14: 8 | F14: 9.4 | G14: 2 | J14: 1.7 | K14: =J14*5 -> 8.5 | L14: =K14/$K$8 -> 1.0493827 | M14: 47061 | N14: =M14/$M$14 -> 1
A15: 2 | B15: 1 | C15: 2 | D15: 1 | E15: 8 | F15: 9.4 | G15: 2 | J15: 1 | K15: =J15*5 -> 5 | L15: =K15/$K$8 -> 0.61728395 | M15: 35337 | N15: =M15/$M$14 -> 0.75087652
A16: 2 | B16: 1 | C16: 4 | D16: 1 | E16: 8 | F16: 9.4 | G16: 2 | J16: 0.76 | K16: =J16*5 -> 3.8 | L16: =K16/$K$8 -> 0.4691358 | M16: 38818 | N16: =M16/$M$14 -> 0.82484435
A17: 2 | B17: 1 | C17: 6 | D17: 1 | E17: 8 | F17: 9.4 | G17: 2 | J17: 0.47 | K17: =J17*5 -> 2.35 | L17: =K17/$K$8 -> 0.29012346 | M17: 36909 | N17: =M17/$M$14 -> 0.78427998
A18: 2 | B18: 1 | C18: 8 | D18: 1 | E18: 8 | F18: 9.4 | G18: 2 | J18: 0.26 | K18: =J18*5 -> 1.3 | L18: =K18/$K$8 -> 0.16049383 | M18: 20974 | N18: =M18/$M$14 -> 0.44567689
A19: 2 | B19: 1 | C19: 10 | D19: 1 | E19: 8 | F19: 9.4 | G19: 2 | J19: 0.15 | K19: =J19*5 -> 0.75 | L19: =K19/$K$8 -> 0.092592593 | M19: 23854 | N19: =M19/$M$14 -> 0.50687406
A20: 3 | B20: 2 | C20: 0 | D20: 1 | E20: 8 | F20: 9.4 | G20: 2 | J20: 1.72 | K20: =J20*5 -> 8.6 | L20: =K20/$K$8 -> 1.0617284 | M20: =AVERAGE(9589,27130) -> 18359.5 | N20: =M14/$M$20 -> 2.5633051
A21: 3 | B21: 2 | C21: 2 | D21: 1 | E21: 8 | F21: 9.4 | G21: 2 | J21: 1.18 | K21: =J21*5 -> 5.9 | L21: =K21/$K$8 -> 0.72839506 | M21: =AVERAGE(31802,22308) -> 27055 | N21: =M15/$M$20 -> 1.9247256
A22: 3 | B22: 2 | C22: 4 | D22: 1 | E22: 8 | F22: 9.4 | G22: 2 | J22: 0.76 | K22: =J22*5 -> 3.8 | L22: =K22/$K$8 -> 0.4691358 | M22: =AVERAGE(27178,36909) -> 32043.5 | N22: =M16/$M$20 -> 2.1143277
A23: 3 | B23: 2 | C23: 6 | D23: 1 | E23: 8 | F23: 9.4 | G23: 2 | J23: 0.46 | K23: =J23*5 -> 2.3 | L23: =K23/$K$8 -> 0.28395062 | M23: =AVERAGE(17601,23134) -> 20367.5 | N23: =M17/$M$20 -> 2.0103489
A24: 3 | B24: 2 | C24: 8 | D24: 1 | E24: 8 | F24: 9.4 | G24: 2 | J24: 0.29 | K24: =J24*5 -> 1.45 | L24: =K24/$K$8 -> 0.17901235 | M24: =AVERAGE(20974,16071) -> 18522.5 | N24: =M18/$M$20 -> 1.1424058
A25: 3 | B25: 2 | C25: 10 | D25: 1 | E25: 8 | F25: 9.4 | G25: 2 | J25: 0.16 | K25: =J25*5 -> 0.8 | L25: =K25/$K$8 -> 0.098765432 | M25: =AVERAGE(4967,16631) -> 10799 | N25: =M19/$M$20 -> 1.2992729
A26: 4 | B26: 1 | C26: 0 | D26: 1 | E26: 8 | F26: 5.5 | G26: 2 | J26: 1.72 | K26: =J26*5 -> 8.6 | L26: =K26/$K$8 -> 1.0617284 | N26: =M20/$M$20 -> 1
A27: 4 | B27: 1 | C27: 2 | D27: 1 | E27: 8 | F27: 5.5 | G27: 2 | J27: 1.04 | K27: =J27*5 -> 5.2 | L27: =K27/$K$8 -> 0.64197531 | N27: =M21/$M$20 -> 1.473624
A28: 4 | B28: 1 | C28: 4 | D28: 1 | E28: 8 | F28: 5.5 | G28: 2 | J28: 0.52 | K28: =J28*5 -> 2.6 | L28: =K28/$K$8 -> 0.32098765 | N28: =M22/$M$20 -> 1.7453362
A29: 4 | B29: 1 | C29: 6 | D29: 1 | E29: 8 | F29: 5.5 | G29: 2 | J29: 0.34 | K29: =J29*5 -> 1.7 | L29: =K29/$K$8 -> 0.20987654 | N29: =M23/$M$20 -> 1.1093712
A30: 4 | B30: 1 | C30: 8 | D30: 1 | E30: 8 | F30: 5.5 | G30: 2 | J30: 0.17 | K30: =J30*5 -> 0.85 | L30: =K30/$K$8 -> 0.10493827 | N30: =M24/$M$20 -> 1.0088782
A31: 4 | B31: 1 | C31: 10 | D31: 1 | E31: 8 | F31: 5.5 | G31: 2 | J31: 0.08 | K31: =J31*5 -> 0.4 | L31: =K31/$K$8 -> 0.049382716 | N31: =M25/$M$20 -> 0.58819685

Sheet dioxane analysis
A1: time(minute) | B1: Test number | C1: experiment replicate | D1: sample replicate | E1: UV | F1: Cl20 (mgCl2/L) | G1: pH | H1: Phosphate buffer (mM) | I1: Dioxane std C0 area | J1: dioxane (microgram/L) | K1: dioxane C/C0
A2: 0 | B2: 2 | C2: 1 | D2: 1 | E2: 1 | F2: 8 | G2: 9.4 | H2: 2 | I2: =AVERAGE(66185,61605,69860,68053) -> 66425.75 | J2: 47061 | K2: =J2/$I$2 -> 0.70847525
A3: 2 | B3: 2 | C3: 1 | D3: 1 | E3: 1 | F3: 8 | G3: 9.4 | H3: 2 | I3: =AVERAGE(66185,61605,69860,68053) -> 66425.75 | J3: 35337 | K3: =J3/$I$2 -> 0.53197743
A4: 4 | B4: 2 | C4: 1 | D4: 1 | E4: 1 | F4: 8 | G4: 9.4 | H4: 2 | I4: =AVERAGE(66185,61605,69860,68053) -> 66425.75 | J4: 38818 | K4: =J4/$I$2 -> 0.58438181
A5: 6 | B5: 2 | C5: 1 | D5: 1 | E5: 1 | F5: 8 | G5: 9.4 | H5: 2 | I5: =AVERAGE(66185,61605,69860,68053) -> 66425.75 | J5: 36909 | K5: =J5/$I$2 -> 0.55564295
A6: 8 | B6: 2 | C6: 1 | D6: 1 | E6: 1 | F6: 8 | G6: 9.4 | H6: 2 | I6: =AVERAGE(66185,61605,69860,68053) -> 66425.75 | J6: 20974 | K6: =J6/$I$2 -> 0.31575105
A7: 10 | B7: 2 | C7: 1 | D7: 1 | E7: 1 | F7: 8 | G7: 9.4 | H7: 2 | I7: =AVERAGE(66185,61605,69860,68053) -> 66425.75 | J7: 23854 | K7: =J7/$I$2 -> 0.35910773
A8: 0 | B8: 3 | C8: 2 | D8: 1 | E8: 1 | F8: 8 | G8: 9.4 | H8: 2 | I8: =AVERAGE(66185,61605,69860,68053) -> 66425.75 | J8: 9589
A9: 2 | B9: 3 | C9: 2 | D9: 1 | E9: 1 | F9: 8 | G9: 9.4 | H9: 2 | I9: =AVERAGE(66185,61605,69860,68053) -> 66425.75 | J9: 31802 | K9: =J9/$I$2 -> 0.47876012
A10: 4 | B10: 3 | C10: 2 | D10: 1 | E10: 1 | F10: 8 | G10: 9.4 | H10: 2 | I10: =AVERAGE(66185,61605,69860,68053) -> 66425.75 | J10: 27178 | K10: =J10/$I$2 -> 0.40914856
A11: 6 | B11: 3 | C11: 2 | D11: 1 | E11: 1 | F11: 8 | G11: 9.4 | H11: 2 | I11: =AVERAGE(66185,61605,69860,68053) -> 66425.75 | J11: 23134 | K11: =J11/$I$2 -> 0.34826856
A12: 8 | B12: 3 | C12: 2 | D12: 1 | E12: 1 | F12: 8 | G12: 9.4 | H12: 2 | I12: =AVERAGE(66185,61605,69860,68053) -> 66425.75 | J12: 20974 | K12: =J12/$I$2 -> 0.31575105
A13: 10 | B13: 3 | C13: 2 | D13: 1 | E13: 1 | F13: 8 | G13: 9.4 | H13: 2 | I13: =AVERAGE(66185,61605,69860,68053) -> 66425.75 | J13: 4967
A14: 0 | B14: 3 | C14: 2 | D14: 2 | E14: 1 | F14: 8 | G14: 9.4 | H14: 2 | I14: =AVERAGE(66185,61605,69860,68053) -> 66425.75 | J14: =27130*1.25 -> 33912.5 | K14: =J14/$I$2 -> 0.51053244
A15: 2 | B15: 3 | C15: 2 | D15: 2 | E15: 1 | F15: 8 | G15: 9.4 | H15: 2 | I15: =AVERAGE(66185,61605,69860,68053) -> 66425.75 | J15: =22308*1.25 -> 27885 | K15: =J15/$I$2 -> 0.41979202
A16: 4 | B16: 3 | C16: 2 | D16: 2 | E16: 1 | F16: 8 | G16: 9.4 | H16: 2 | I16: =AVERAGE(66185,61605,69860,68053) -> 66425.75 | J16: =36909*1.25 -> 46136.25
A17: 6 | B17: 3 | C17: 2 | D17: 2 | E17: 1 | F17: 8 | G17: 9.4 | H17: 2 | I17: =AVERAGE(66185,61605,69860,68053) -> 66425.75 | J17: =17601*1.25 -> 22001.25 | K17: =J17/$I$2 -> 0.33121568
A18: 8 | B18: 3 | C18: 2 | D18: 2 | E18: 1 | F18: 8 | G18: 9.4 | H18: 2 | I18: =AVERAGE(66185,61605,69860,68053) -> 66425.75 | J18: =16071*1.25 -> 20088.75 | K18: =J18/$I$2 -> 0.30242414
A19: 10 | B19: 3 | C19: 2 | D19: 2 | E19: 1 | F19: 8 | G19: 9.4 | H19: 2 | I19: =AVERAGE(66185,61605,69860,68053) -> 66425.75 | J19: =16631*1.25 -> 20788.75 | K19: =J19/$I$2 -> 0.31296222

Sheet week5reox
A1: time(minute) | B1: Test number | C1: experiment replicate | D1: sample replicate | E1: UV | F1: Cl20 (mgCl2/L) | G1: Cl2free (mgCl2/L) diluted x5 | H1: Cl2free (mgCl2/L) | I1: Cl2free C/C0 | J1: pH | K1: Phosphate buffer (mM) | L1: Dioxane std C0 area | M1: dioxane (microgram/L) | N1: dioxane C/C0
A2: 0 | D2: 1 | E2: 1 | F2: 8.3 | G2: 1.66 | H2: =G2*5 -> 8.3 | I2: =H2/F2 -> 1 | J2: 5.5 | K2: 2 | L2: 80.92 | M2: 80.92 | N2: =M2/$L$2 -> 1
A3: 0.43 | D3: 1 | E3: 1 | F3: 8.3 | G3: 1.58 | H3: =G3*5 -> 7.9 | I3: =H3/F3 -> 0.95180723 | J3: 5.5 | K3: 2 | M3: 53.07 | N3: =M3/$L$2 -> 0.65583292
A4: 0.66 | D4: 1 | E4: 1 | F4: 8.3 | G4: 1.46 | H4: =G4*5 -> 7.3 | I4: =H4/F4 -> 0.87951807 | J4: 5.5 | K4: 2 | M4: 38.04 | N4: =M4/$L$2 -> 0.47009392
A5: 1 | D5: 1 | E5: 1 | F5: 8.3 | G5: 1.33 | H5: =G5*5 -> 6.65 | I5: =H5/F5 -> 0.80120482 | J5: 5.5 | K5: 2 | M5: 21.28 | N5: =M5/$L$2 -> 0.26297578
A6: 1.33 | D6: 1 | E6: 1 | F6: 8.3 | G6: 1.23 | H6: =G6*5 -> 6.15 | I6: =H6/F6 -> 0.74096386 | J6: 5.5 | K6: 2 | M6: 11.26 | N6: =M6/$L$2 -> 0.13914978
A7: 1.76 | D7: 1 | E7: 1 | F7: 8.3 | G7: 1.08 | H7: =G7*5 -> 5.4 | I7: =H7/F7 -> 0.65060241 | J7: 5.5 | K7: 2 | M7: 3.16 | N7: =M7/$L$2 -> 0.039050914
A8: 2 | D8: 1 | E8: 1 | F8: 8.3 | G8: 1 | H8: =G8*5 -> 5 | I8: =H8/F8 -> 0.60240964 | J8: 5.5 | K8: 2 | M8: 3.055 | N8: =M8/$L$2 -> 0.037753337
A9: 4 | D9: 1 | E9: 1 | F9: 8.3 | G9: 0.52 | H9: =G9*5 -> 2.6 | I9: =H9/F9 -> 0.31325301 | J9: 5.5 | K9: 2 | M9: 0 | N9: =M9/$L$2 -> 0
A10: 6 | D10: 1 | E10: 1 | F10: 8.3 | G10: 0.26 | H10: =G10*5 -> 1.3 | I10: =H10/F10 -> 0.15662651 | J10: 5.5 | K10: 2 | M10: 0 | N10: =M10/$L$2 -> 0
A11: 8 | D11: 1 | E11: 1 | F11: 8.3 | G11: 0.13 | H11: =G11*5 -> 0.65 | I11: =H11/F11 -> 0.078313253 | J11: 5.5 | K11: 2 | M11: 0 | N11: =M11/$L$2 -> 0
A12: 10 | D12: 1 | E12: 1 | F12: 8.3 | G12: 0.05 | H12: =G12*5 -> 0.25 | I12: =H12/F12 -> 0.030120482 | J12: 5.5 | K12: 2 | M12: 0 | N12: =M12/$L$2 -> 0
A13: 0 | D13: 2 | E13: 1 | F13: 8.3 | G13: 1.66 | H13: =G13*5 -> 8.3 | I13: =H13/F13 -> 1 | J13: 5.5 | K13: 2 | L13: 80.49 | M13: 80.92 | N13: =M13/$L$13 -> 1.0053423
A14: 0.43 | D14: 2 | E14: 1 | F14: 8.3 | G14: 1.58 | H14: =G14*5 -> 7.9 | I14: =H14/F14 -> 0.95180723 | J14: 5.5 | K14: 2 | M14: 49.43 | N14: =M14/$L$13 -> 0.61411355
A15: 0.66 | D15: 2 | E15: 1 | F15: 8.3 | G15: 1.46 | H15: =G15*5 -> 7.3 | I15: =H15/F15 -> 0.87951807 | J15: 5.5 | K15: 2 | M15: 39.04 | N15: =M15/$L$13 -> 0.4850292
A16: 1 | D16: 2 | E16: 1 | F16: 8.3 | G16: 1.33 | H16: =G16*5 -> 6.65 | I16: =H16/F16 -> 0.80120482 | J16: 5.5 | K16: 2 | M16: 25.1 | N16: =M16/$L$13 -> 0.31183998
A17: 1.33 | D17: 2 | E17: 1 | F17: 8.3 | G17: 1.23 | H17: =G17*5 -> 6.15 | I17: =H17/F17 -> 0.74096386 | J17: 5.5 | K17: 2 | M17: 12.1 | N17: =M17/$L$13 -> 0.15032923
A18: 1.76 | D18: 2 | E18: 1 | F18: 8.3 | G18: 1.08 | H18: =G18*5 -> 5.4 | I18: =H18/F18 -> 0.65060241 | J18: 5.5 | K18: 2 | M18: 4.56 | N18: =M18/$L$13 -> 0.056653
A19: 2 | D19: 2 | E19: 1 | F19: 8.3 | G19: 1 | H19: =G19*5 -> 5 | I19: =H19/F19 -> 0.60240964 | J19: 5.5 | K19: 2 | M19: 3.15 | N19: =M19/$L$13 -> 0.039135296
A20: 4 | D20: 2 | E20: 1 | F20: 8.3 | G20: 0.52 | H20: =G20*5 -> 2.6 | I20: =H20/F20 -> 0.31325301 | J20: 5.5 | K20: 2 | M20: 0 | N20: =M20/$L$13 -> 0
A21: 6 | D21: 2 | E21: 1 | F21: 8.3 | G21: 0.26 | H21: =G21*5 -> 1.3 | I21: =H21/F21 -> 0.15662651 | J21: 5.5 | K21: 2 | M21: 0 | N21: =M21/$L$13 -> 0
A22: 8 | D22: 2 | E22: 1 | F22: 8.3 | G22: 0.13 | H22: =G22*5 -> 0.65 | I22: =H22/F22 -> 0.078313253 | J22: 5.5 | K22: 2 | M22: 0 | N22: =M22/$L$13 -> 0
A23: 10 | D23: 2 | E23: 1 | F23: 8.3 | G23: 0.05 | H23: =G23*5 -> 0.25 | I23: =H23/F23 -> 0.030120482 | J23: 5.5 | K23: 2 | M23: 0 | N23: =M23/$L$13 -> 0

Sheet week6CBD
A1: time(minute) | B1: Test number | C1: experiment replicate | D1: sample replicate | E1: UV | F1: Cl20 (mgCl2/L) | G1: Cl2free (mgCl2/L) diluted x5 | H1: Cl2free (mgCl2/L) | I1: Cl2free C/C0 | J1: pH | K1: Phosphate buffer (mM) | L1: Dioxane std C0 | M1: dioxane (microgram/L) | N1: dioxane C/C0
A2: 0 | C2: 1 | D2: 1 | E2: 1 | F2: 8.45 | G2: 1.69 | H2: =G2*5 -> 8.45 | I2: =H2/F2 -> 1 | J2: 5.5 | K2: 2 | M2: 39.11 | N2: =M2/$M$2 -> 1
A3: 5 | C3: 1 | D3: 1 | E3: 1 | F3: 8.45 | G3: 1.63 | H3: =G3*5 -> 8.15 | I3: =H3/F3 -> 0.96449704 | J3: 5.5 | K3: 2 | M3: 39.12 | N3: =M3/$M$2 -> 1.0002557
A4: 10 | C4: 1 | D4: 1 | E4: 1 | F4: 8.45 | G4: 1.5 | H4: =G4*5 -> 7.5 | I4: =H4/F4 -> 0.88757396 | J4: 5.5 | K4: 2 | M4: 30.83 | N4: =M4/$M$2 -> 0.78828944
A5: 20 | C5: 1 | D5: 1 | E5: 1 | F5: 8.45 | G5: 1.39 | H5: =G5*5 -> 6.95 | I5: =H5/F5 -> 0.82248521 | J5: 5.5 | K5: 2 | M5: 23.24 | N5: =M5/$M$2 -> 0.59422143
A6: 30 | C6: 1 | D6: 1 | E6: 1 | F6: 8.45 | G6: 1.22 | H6: =G6*5 -> 6.1 | I6: =H6/F6 -> 0.72189349 | J6: 5.5 | K6: 2 | M6: 11.66 | N6: =M6/$M$2 -> 0.29813347
A7: 0 | C7: 1 | D7: 2 | E7: 1 | F7: 8.45 | J7: 5.5 | K7: 2 | M7: 38.22 | N7: =M7/$M$7 -> 1
A8: 5 | C8: 1 | D8: 2 | E8: 1 | F8: 8.45 | J8: 5.5 | K8: 2 | M8: 41.36 | N8: =M8/$M$7 -> 1.0821559
A9: 10 | C9: 1 | D9: 2 | E9: 1 | F9: 8.45 | J9: 5.5 | K9: 2 | M9: 31.78 | N9: =M9/$M$7 -> 0.83150183
A10: 20 | C10: 1 | D10: 2 | E10: 1 | F10: 8.45 | J10: 5.5 | K10: 2 | M10: 22.88 | N10: =M10/$M$7 -> 0.59863946
A11: 30 | C11: 1 | D11: 2 | E11: 1 | F11: 8.45 | J11: 5.5 | K11: 2 | M11: 9.07 | N11: =M11/$M$7 -> 0.23731031
A12: 0 | C12: 1 | D12: 1 | E12: 1 | F12: 8.2 | G12: 1.64 | H12: =G12*5 -> 8.2 | I12: =H12/F12 -> 1 | J12: 5.5 | K12: 2 | M12: 47.57 | N12: =M12/$M$12 -> 1
A13: 5 | C13: 2 | D13: 1 | E13: 1 | F13: 8.2 | G13: 1.56 | H13: =G13*5 -> 7.8 | I13: =H13/F13 -> 0.95121951 | J13: 5.5 | K13: 2 | M13: 41.57 | N13: =M13/$M$12 -> 0.87387009
A14: 10 | C14: 2 | D14: 1 | E14: 1 | F14: 8.2 | G14: 1.48 | H14: =G14*5 -> 7.4 | I14: =H14/F14 -> 0.90243902 | J14: 5.5 | K14: 2 | M14: 38.68 | N14: =M14/$M$12 -> 0.81311751
A15: 20 | C15: 2 | D15: 1 | E15: 1 | F15: 8.2 | G15: 1.43 | H15: =G15*5 -> 7.15 | I15: =H15/F15 -> 0.87195122 | J15: 5.5 | K15: 2 | M15: 27.63 | N15: =M15/$M$12 -> 0.58082825
A16: 30 | C16: 2 | D16: 1 | E16: 1 | F16: 8.2 | G16: 1.23 | H16: =G16*5 -> 6.15 | I16: =H16/F16 -> 0.75 | J16: 5.5 | K16: 2 | M16: 23.36 | N16: =M16/$M$12 -> 0.4910658
A17: 0 | C17: 2 | D17: 2 | E17: 1 | F17: 8.2 | J17: 5.5 | K17: 2 | M17: 55.68 | N17: =M17/$M$17 -> 1
A18: 5 | C18: 2 | D18: 2 | E18: 1 | F18: 8.2 | J18: 5.5 | K18: 2 | M18: 48.18 | N18: =M18/$M$17 -> 0.86530172
A19: 10 | C19: 2 | D19: 2 | E19: 1 | F19: 8.2 | J19: 5.5 | K19: 2 | M19: 41.43 | N19: =M19/$M$17 -> 0.74407328
A20: 20 | C20: 2 | D20: 2 | E20: 1 | F20: 8.2 | J20: 5.5 | K20: 2 | M20: 27.85 | N20: =M20/$M$17 -> 0.5001796
A21: 30 | C21: 2 | D21: 2 | E21: 1 | F21: 8.2 | J21: 5.5 | K21: 2 | M21: 23.19 | N21: =M21/$M$17 -> 0.41648707

Sheet week6reox
A1: time(minute) | B1: Test number | C1: experiment replicate | D1: sample replicate | E1: UV | F1: Cl20 (mgCl2/L) | G1: Cl2free (mgCl2/L) diluted x5 | H1: Cl2free (mgCl2/L) | I1: Cl2free C/C0 | J1: pH | K1: Phosphate buffer (mM) | L1: Dioxane std C0 area | M1: dioxane (microgram/L) | N1: dioxane C/C0
A2: 0 | C2: 1 | D2: 1 | E2: 1 | F2: 8.25 | G2: 1.65 | H2: =G2*5 -> 8.25 | I2: =H2/F2 -> 1 | J2: 5.5 | K2: 2 | M2: 36.61 | N2: =M2/$M$2 -> 1
A3: 0.43 | C3: 1 | D3: 1 | E3: 1 | F3: 8.25 | G3: 1.48 | H3: =G3*5 -> 7.4 | I3: =H3/F3 -> 0.8969697 | J3: 5.5 | K3: 2 | M3: 32.36 | N3: =M3/$M$2 -> 0.8839115
A4: 0.66 | C4: 1 | D4: 1 | E4: 1 | F4: 8.25 | G4: 1.33 | H4: =G4*5 -> 6.65 | I4: =H4/F4 -> 0.80606061 | J4: 5.5 | K4: 2 | M4: 22.04 | N4: =M4/$M$2 -> 0.60202131
A5: 1 | C5: 1 | D5: 1 | E5: 1 | F5: 8.25 | G5: 1.27 | H5: =G5*5 -> 6.35 | I5: =H5/F5 -> 0.76969697 | J5: 5.5 | K5: 2 | M5: 12.56 | N5: =M5/$M$2 -> 0.34307566
A6: 1.33 | C6: 1 | D6: 1 | E6: 1 | F6: 8.25 | G6: 1.21 | H6: =G6*5 -> 6.05 | I6: =H6/F6 -> 0.73333333 | J6: 5.5 | K6: 2 | M6: 9.12 | N6: =M6/$M$2 -> 0.24911226
A7: 1.76 | C7: 1 | D7: 1 | E7: 1 | F7: 8.25 | G7: 1.06 | H7: =G7*5 -> 5.3 | I7: =H7/F7 -> 0.64242424 | J7: 5.5 | K7: 2 | M7: 4.35 | N7: =M7/$M$2 -> 0.11881999
A8: 2 | C8: 1 | D8: 1 | E8: 1 | F8: 8.25 | G8: 0.87 | H8: =G8*5 -> 4.35 | I8: =H8/F8 -> 0.52727273 | J8: 5.5 | K8: 2 | M8: 4.31 | N8: =M8/$M$2 -> 0.1177274
A9: 0 | C9: 1 | D9: 2 | E9: 1 | F9: 8.25 | J9: 5.5 | K9: 2 | M9: 34.44 | N9: =M9/$M$9 -> 1
A10: 0.43 | C10: 1 | D10: 2 | E10: 1 | F10: 8.25 | J10: 5.5 | K10: 2 | M10: 32.56 | N10: =M10/$M$9 -> 0.94541231
A11: 0.66 | C11: 1 | D11: 2 | E11: 1 | F11: 8.25 | J11: 5.5 | K11: 2 | M11: 21.73 | N11: =M11/$M$9 -> 0.63095238
A12: 1 | C12: 1 | D12: 2 | E12: 1 | F12: 8.25 | J12: 5.5 | K12: 2 | M12: 11.57 | N12: =M12/$M$9 -> 0.33594657
A13: 1.33 | C13: 1 | D13: 2 | E13: 1 | F13: 8.25 | J13: 5.5 | K13: 2 | M13: 7.54 | N13: =M13/$M$9 -> 0.21893148
A14: 1.76 | C14: 1 | D14: 2 | E14: 1 | F14: 8.25 | J14: 5.5 | K14: 2 | M14: 4.49 | N14: =M14/$M$9 -> 0.13037166
A15: 2 | C15: 1 | D15: 2 | E15: 1 | F15: 8.25 | J15: 5.5 | K15: 2 | M15: 3.99 | N15: =M15/$M$9 -> 0.11585366
A16: 0 | C16: 2 | D16: 1 | E16: 1 | F16: 8.45 | G16: 1.69 | H16: =G16*5 -> 8.45 | I16: =H16/F16 -> 1 | J16: 5.5 | K16: 2 | M16: 46.94 | N16: =M16/$M$16 -> 1
A17: 0.43 | C17: 2 | D17: 1 | E17: 1 | F17: 8.45 | G17: 1.56 | H17: =G17*5 -> 7.8 | I17: =H17/F17 -> 0.92307692 | J17: 5.5 | K17: 2 | M17: 30.93 | N17: =M17/$M$16 -> 0.65892629
A18: 0.66 | C18: 2 | D18: 1 | E18: 1 | F18: 8.45 | G18: 1.38 | H18: =G18*5 -> 6.9 | I18: =H18/F18 -> 0.81656805 | J18: 5.5 | K18: 2 | M18: 19.45 | N18: =M18/$M$16 -> 0.41435876
A19: 1 | C19: 2 | D19: 1 | E19: 1 | F19: 8.45 | G19: 1.28 | H19: =G19*5 -> 6.4 | I19: =H19/F19 -> 0.75739645 | J19: 5.5 | K19: 2 | M19: 12.65 | N19: =M19/$M$16 -> 0.26949297
A20: 1.33 | C20: 2 | D20: 1 | E20: 1 | F20: 8.45 | G20: 1.12 | H20: =G20*5 -> 5.6 | I20: =H20/F20 -> 0.66272189 | J20: 5.5 | K20: 2 | M20: 6.74 | N20: =M20/$M$16 -> 0.14358756
A21: 1.76 | C21: 2 | D21: 1 | E21: 1 | F21: 8.45 | G21: 1 | H21: =G21*5 -> 5 | I21: =H21/F21 -> 0.59171598 | J21: 5.5 | K21: 2 | M21: 5.07 | N21: =M21/$M$16 -> 0.10801023
A22: 2 | C22: 2 | D22: 1 | E22: 1 | F22: 8.45 | G22: 0.88 | H22: =G22*5 -> 4.4 | I22: =H22/F22 -> 0.52071006 | J22: 5.5 | K22: 2 | M22: 3.89 | N22: =M22/$M$16 -> 0.082871751
A23: 0 | C23: 2 | D23: 2 | E23: 1 | F23: 8.45 | J23: 5.5 | K23: 2 | M23: 43.52 | N23: =M23/$M$23 -> 1
A24: 0.43 | C24: 2 | D24: 2 | E24: 1 | F24: 8.45 | J24: 5.5 | K24: 2 | M24: 30.11 | N24: =M24/$M$23 -> 0.69186581
A25: 0.66 | C25: 2 | D25: 2 | E25: 1 | F25: 8.45 | J25: 5.5 | K25: 2 | M25: 23.48 | N25: =M25/$M$23 -> 0.53952206
A26: 1 | C26: 2 | D26: 2 | E26: 1 | F26: 8.45 | J26: 5.5 | K26: 2 | M26: 14.51 | N26: =M26/$M$23 -> 0.33340993
A27: 1.33 | C27: 2 | D27: 2 | E27: 1 | F27: 8.45 | J27: 5.5 | K27: 2 | M27: 7.15 | N27: =M27/$M$23 -> 0.16429228
A28: 1.76 | C28: 2 | D28: 2 | E28: 1 | F28: 8.45 | J28: 5.5 | K28: 2 | M28: 5.29 | N28: =M28/$M$23 -> 0.12155331
A29: 2 | C29: 2 | D29: 2 | E29: 1 | F29: 8.45 | J29: 5.5 | K29: 2 | M29: 3.9 | N29: =M29/$M$23 -> 0.089613971

Sheet week7reox
A1: time(minute) | B1: Test number | C1: experiment replicate | D1: sample replicate | E1: UV | F1: Cl20 (mgCl2/L) | G1: Cl2free (mgCl2/L) diluted x5 | H1: Cl2free (mgCl2/L) | I1: Cl2free C/C0 | J1: pH | K1: Phosphate buffer (mM) | L1: Dioxane std C0 area | M1: dioxane (microgram/L) | N1: dioxane C/C0 | O1: sucralose (microgram/L | P1: sucralose C/C0 | Q1: caffeine (area) | R1: caffeine C/C0
A2: 0 | C2: 1 | D2: 1 | E2: 1 | F2: 8.9 | G2: 1.78 | H2: =G2*5 -> 8.9 | I2: =H2/F2 -> 1 | J2: 9.3 | K2: 2 | M2: 85.99 | N2: =M2/$M$2 -> 1 | O2: 3966 | Q2: 714791.22
A3: 0.43 | C3: 1 | D3: 1 | E3: 1 | F3: 8.9 | G3: 1.66 | H3: =G3*5 -> 8.3 | I3: =H3/F3 -> 0.93258427 | J3: 9.3 | K3: 2 | M3: 80.61 | N3: =M3/$M$2 -> 0.93743459 | O3: 4173 | Q3: 126444.95
A4: 0.66 | C4: 1 | D4: 1 | E4: 1 | F4: 8.9 | G4: 1.49 | H4: =G4*5 -> 7.45 | I4: =H4/F4 -> 0.83707865 | J4: 9.3 | K4: 2 | M4: 80.5 | N4: =M4/$M$2 -> 0.93615537 | O4: 4271 | Q4: 21505.168
A5: 1 | C5: 1 | D5: 1 | E5: 1 | F5: 8.9 | G5: 1.37 | H5: =G5*5 -> 6.85 | I5: =H5/F5 -> 0.76966292 | J5: 9.3 | K5: 2 | M5: 77.79 | N5: =M5/$M$2 -> 0.90464007 | O5: 4075 | Q5: 3611.8262
A6: 1.33 | C6: 1 | D6: 1 | E6: 1 | F6: 8.9 | G6: 1.25 | H6: =G6*5 -> 6.25 | I6: =H6/F6 -> 0.70224719 | J6: 9.3 | K6: 2 | M6: 74.51 | N6: =M6/$M$2 -> 0.8664961 | O6: 3926 | Q6: 3336.8696
A7: 1.76 | C7: 1 | D7: 1 | E7: 1 | F7: 8.9 | G7: 1.13 | H7: =G7*5 -> 5.65 | I7: =H7/F7 -> 0.63483146 | J7: 9.3 | K7: 2 | M7: 69.55 | N7: =M7/$M$2 -> 0.80881498 | O7: 3936 | Q7: 1343.9133
A8: 2 | C8: 1 | D8: 1 | E8: 1 | F8: 8.9 | G8: 1.03 | H8: =G8*5 -> 5.15 | I8: =H8/F8 -> 0.57865169 | J8: 9.3 | K8: 2 | M8: 68.03 | N8: =M8/$M$2 -> 0.7911385 | O8: 3929 | Q8: 1353.5619
A9: 0 | C9: 1 | D9: 2 | E9: 1 | F9: 8.9 | H9: =G9*5 -> 0 | J9: 9.3 | K9: 2 | M9: 82.68 | N9: =M9/$M$9 -> 1 | O9: 4255 | Q9: 492172.7
A10: 0.43 | C10: 1 | D10: 2 | E10: 1 | F10: 8.9 | H10: =G10*5 -> 0 | J10: 9.3 | K10: 2 | M10: 84.51 | N10: =M10/$M$9 -> 1.0221335 | O10: 4262 | Q10: 128644.98
A11: 0.66 | C11: 1 | D11: 2 | E11: 1 | F11: 8.9 | H11: =G11*5 -> 0 | J11: 9.3 | K11: 2 | M11: 80.85 | N11: =M11/$M$9 -> 0.97786647 | O11: 4195 | Q11: 21362.242
A12: 1 | C12: 1 | D12: 2 | E12: 1 | F12: 8.9 | H12: =G12*5 -> 0 | J12: 9.3 | K12: 2 | M12: 75.71 | N12: =M12/$M$9 -> 0.91569908 | O12: 4242 | Q12: 1927.6935
A13: 1.33 | C13: 1 | D13: 2 | E13: 1 | F13: 8.9 | H13: =G13*5 -> 0 | J13: 9.3 | K13: 2 | M13: 74.98 | N13: =M13/$M$9 -> 0.90686986 | O13: 4020 | Q13: 3066.853
A14: 1.76 | C14: 1 | D14: 2 | E14: 1 | F14: 8.9 | H14: =G14*5 -> 0 | J14: 9.3 | K14: 2 | M14: 77.33 | N14: =M14/$M$9 -> 0.93529269 | O14: 4008 | Q14: 1406.2845
A15: 2 | C15: 1 | D15: 2 | E15: 1 | F15: 8.9 | H15: =G15*5 -> 0 | J15: 9.3 | K15: 2 | M15: 67.57 | N15: =M15/$M$9 -> 0.81724722 | O15: 3845 | Q15: 3201.1437
A16: 0 | C16: 2 | D16: 1 | E16: 1 | F16: 8.5 | G16: 1.7 | H16: =G16*5 -> 8.5 | I16: =H16/F16 -> 1 | J16: 8.95 | K16: 2 | M16: 81.13 | N16: =M16/$M$16 -> 1 | O16: 4407 | P16: =O16/$O$16 -> 1 | Q16: 667752.29 | R16: =Q16/$Q$16 -> 1
A17: 0.43 | C17: 2 | D17: 1 | E17: 1 | F17: 8.5 | G17: 1.58 | H17: =G17*5 -> 7.9 | I17: =H17/F17 -> 0.92941176 | J17: 8.95 | K17: 2 | M17: 81.82 | N17: =M17/$M$16 -> 1.0085049 | O17: 4159 | P17: =O17/$O$16 -> 0.94372589 | Q17: 132344.4 | R17: =Q17/$Q$16 -> 0.19819385
A18: 0.66 | C18: 2 | D18: 1 | E18: 1 | F18: 8.5 | G18: 1.37 | H18: =G18*5 -> 6.85 | I18: =H18/F18 -> 0.80588235 | J18: 8.95 | K18: 2 | M18: 75.48 | N18: =M18/$M$16 -> 0.93035868 | O18: 4095 | P18: =O18/$O$16 -> 0.92920354 | Q18: 19133.21 | R18: =Q18/$Q$16 -> 0.028653155
A19: 1 | C19: 2 | D19: 1 | E19: 1 | F19: 8.5 | G19: 1.28 | H19: =G19*5 -> 6.4 | I19: =H19/F19 -> 0.75294118 | J19: 8.95 | K19: 2 | M19: 83.2 | N19: =M19/$M$16 -> 1.0255146 | O19: 3756 | P19: =O19/$O$16 -> 0.85228046 | Q19: 4342.916 | R19: =Q19/$Q$16 -> 0.0065037831
A20: 1.33 | C20: 2 | D20: 1 | E20: 1 | F20: 8.5 | G20: 1.2 | H20: =G20*5 -> 6 | I20: =H20/F20 -> 0.70588235 | J20: 8.95 | K20: 2 | M20: 82.71 | N20: =M20/$M$16 -> 1.0194749 | O20: 2949 | P20: =O20/$O$16 -> 0.6691627 | Q20: 1769.9951 | R20: =Q20/$Q$16 -> 0.0026506762
A21: 1.76 | C21: 2 | D21: 1 | E21: 1 | F21: 8.5 | G21: 1.03 | H21: =G21*5 -> 5.15 | I21: =H21/F21 -> 0.60588235 | J21: 8.95 | K21: 2 | M21: 63.96 | N21: =M21/$M$16 -> 0.78836435 | O21: 2910 | P21: =O21/$O$16 -> 0.66031314 | R21: =Q21/$Q$16 -> 0
A22: 2 | C22: 2 | D22: 1 | E22: 1 | F22: 8.5 | G22: 0.94 | H22: =G22*5 -> 4.7 | I22: =H22/F22 -> 0.55294118 | J22: 8.95 | K22: 2 | M22: 85.9 | N22: =M22/$M$16 -> 1.0587945 | O22: 2832 | P22: =O22/$O$16 -> 0.64261402 | R22: =Q22/$Q$16 -> 0
A23: 0 | C23: 2 | D23: 2 | E23: 1 | F23: 8.5 | H23: =G23*5 -> 0 | J23: 8.95 | K23: 2 | M23: 91.75 | N23: =M23/$M$23 -> 1 | O23: 4348 | P23: =O23/$O$23 -> 1 | Q23: 667270.31 | R23: =Q23/$Q$23 -> 1
A24: 0.43 | C24: 2 | D24: 2 | E24: 1 | F24: 8.5 | H24: =G24*5 -> 0 | J24: 8.95 | K24: 2 | M24: 92.56 | N24: =M24/$M$23 -> 1.0088283 | O24: 4226 | P24: =O24/$O$23 -> 0.97194112 | Q24: 130243.53 | R24: =Q24/$Q$23 -> 0.19518856
A25: 0.66 | C25: 2 | D25: 2 | E25: 1 | F25: 8.5 | H25: =G25*5 -> 0 | J25: 8.95 | K25: 2 | M25: 86.82 | N25: =M25/$M$23 -> 0.94626703 | O25: 4140 | P25: =O25/$O$23 -> 0.95216191 | Q25: 18804.52 | R25: =Q25/$Q$23 -> 0.028181263
A26: 1 | C26: 2 | D26: 2 | E26: 1 | F26: 8.5 | H26: =G26*5 -> 0 | J26: 8.95 | K26: 2 | M26: 75.37 | N26: =M26/$M$23 -> 0.82147139 | O26: 3188 | P26: =O26/$O$23 -> 0.73321067 | Q26: 7103.4716 | R26: =Q26/$Q$23 -> 0.010645568
A27: 1.33 | C27: 2 | D27: 2 | E27: 1 | F27: 8.5 | H27: =G27*5 -> 0 | J27: 8.95 | K27: 2 | M27: 87.57 | N27: =M27/$M$23 -> 0.95444142 | O27: 3009 | P27: =O27/$O$23 -> 0.69204232 | Q27: 1703.0614 | R27: =Q27/$Q$23 -> 0.0025522812
A28: 1.76 | C28: 2 | D28: 2 | E28: 1 | F28: 8.5 | H28: =G28*5 -> 0 | J28: 8.95 | K28: 2 | M28: 86.81 | N28: =M28/$M$23 -> 0.94615804 | O28: 3003 | P28: =O28/$O$23 -> 0.69066237
A29: 2 | C29: 2 | D29: 2 | E29: 1 | F29: 8.5 | H29: =G29*5 -> 0 | J29: 8.95 | K29: 2 | M29: 76.5 | N29: =M29/$M$23 -> 0.83378747 | O29: 2837 | P29: =O29/$O$23 -> 0.6524839
A30: 0 | C30: 2 | D30: 1 | E30: 1 | F30: 8 | G30: 1.6 | H30: =G30*5 -> 8 | I30: =H30/F30 -> 1 | J30: 9.17 | K30: 2 | M30: 81.28 | N30: =M30/$M$30 -> 1
A31: 0.43 | C31: 2 | D31: 1 | E31: 1 | F31: 8 | G31: 1.53 | H31: =G31*5 -> 7.65 | I31: =H31/F31 -> 0.95625 | J31: 9.17 | K31: 2 | M31: 77.36 | N31: =M31/$M$16 -> 0.95353137
A32: 0.66 | C32: 2 | D32: 1 | E32: 1 | F32: 8 | G32: 1.44 | H32: =G32*5 -> 7.2 | I32: =H32/F32 -> 0.9 | J32: 9.17 | K32: 2 | M32: 81.23 | N32: =M32/$M$16 -> 1.0012326
A33: 1 | C33: 2 | D33: 1 | E33: 1 | F33: 8 | G33: 1.33 | H33: =G33*5 -> 6.65 | I33: =H33/F33 -> 0.83125 | J33: 9.17 | K33: 2 | M33: 83 | N33: =M33/$M$16 -> 1.0230494
A34: 1.33 | C34: 2 | D34: 1 | E34: 1 | F34: 8 | G34: 1.19 | H34: =G34*5 -> 5.95 | I34: =H34/F34 -> 0.74375 | J34: 9.17 | K34: 2 | M34: 79.49 | N34: =M34/$M$16 -> 0.97978553
A35: 1.76 | C35: 2 | D35: 1 | E35: 1 | F35: 8 | G35: 1.07 | H35: =G35*5 -> 5.35 | I35: =H35/F35 -> 0.66875 | J35: 9.17 | K35: 2 | M35: 83.14 | N35: =M35/$M$16 -> 1.0247751
A36: 2 | C36: 2 | D36: 1 | E36: 1 | F36: 8 | G36: 0.97 | H36: =G36*5 -> 4.85 | I36: =H36/F36 -> 0.60625 | J36: 9.17 | K36: 2 | M36: 75.43 | N36: =M36/$M$16 -> 0.92974239
A37: 0 | C37: 2 | D37: 2 | E37: 1 | F37: 8 | H37: =G37*5 -> 0 | J37: 9.17 | K37: 2 | M37: 84.35 | N37: =M37/$M$23 -> 0.91934605
A38: 0.43 | C38: 2 | D38: 2 | E38: 1 | F38: 8 | H38: =G38*5 -> 0 | J38: 9.17 | K38: 2 | M38: 83.43 | N38: =M38/$M$23 -> 0.9093188
A39: 0.66 | C39: 2 | D39: 2 | E39: 1 | F39: 8 | H39: =G39*5 -> 0 | J39: 9.17 | K39: 2 | M39: 80.71 | N39: =M39/$M$23 -> 0.87967302
A40: 1 | C40: 2 | D40: 2 | E40: 1 | F40: 8 | H40: =G40*5 -> 0 | J40: 9.17 | K40: 2 | M40: 87.19 | N40: =M40/$M$23 -> 0.95029973
...

Sheet week8reox ph5&8
A1: time(minute) | B1: pH | C1: experiment replicate | D1: sample replicate | E1: UV | F1: Nominal Cl2(0) | G1: Cl2free (mgCl2/L) diluted x5 | H1: DPD dilution factor | I1: Cl2free (mgCl2/L) | J1: Cl2free C/C0 | K1: Phosphate buffer (mM) | L1: dioxane (microgram/L) | M1: dioxane C/C0 | N1: caffeine (microgam/L) | O1: caffeine C/C0 | P1: sucralose (microgram/L | Q1: sucralose C/C0
A2: 0 | B2: 9.29 | C2: 1 | D2: 1 | E2: 1 | F2: 10 | G2: 1.87 | H2: 5 | I2: =G2*'week8reox ph5&8'!$H2 -> 9.35 | J2: =I2/$I$2 -> 1 | K2: 2 | L2: 94.348183 | M2: =L2/$L$2 -> 1 | N2: 117.25672 | O2: =N2/$N$2 -> 1 | P2: 114.53914 | Q2: =P2/$P$2 -> 1
A3: 0.43 | B3: 9.29 | C3: 1 | D3: 1 | E3: 1 | F3: 10 | G3: 1.66 | H3: 5 | I3: =G3*'week8reox ph5&8'!$H3 -> 8.3 | J3: =I3/$I$2 -> 0.88770053 | K3: 2 | L3: 91.539163 | M3: =L3/$L$2 -> 0.9702271 | N3: 5.7855528 | O3: =N3/$N$2 -> 0.049340904 | P3: 92.545622 | Q3: =P3/$P$2 -> 0.80798254
A4: 0.66 | B4: 9.29 | C4: 1 | D4: 1 | E4: 1 | F4: 10 | G4: 1.55 | H4: 5 | I4: =G4*'week8reox ph5&8'!$H4 -> 7.75 | J4: =I4/$I$2 -> 0.82887701 | K4: 2 | L4: 90.24168 | M4: =L4/$L$2 -> 0.95647503 | N4: 0 | O4: =N4/$N$2 -> 0 | P4: 92.215961 | Q4: =P4/$P$2 -> 0.8051044
A5: 1 | B5: 9.29 | C5: 1 | D5: 1 | E5: 1 | F5: 10 | G5: 1.39 | H5: 5 | I5: =G5*'week8reox ph5&8'!$H5 -> 6.95 | J5: =I5/$I$2 -> 0.74331551 | K5: 2 | L5: 82.94843 | M5: =L5/$L$2 -> 0.87917359 | N5: 0 | O5: =N5/$N$2 -> 0 | P5: 107.73639 | Q5: =P5/$P$2 -> 0.94060768
A6: 1.33 | B6: 9.29 | C6: 1 | D6: 1 | E6: 1 | F6: 10 | G6: 1.24 | H6: 5 | I6: =G6*'week8reox ph5&8'!$H6 -> 6.2 | J6: =I6/$I$2 -> 0.6631016 | K6: 2 | L6: 85.105975 | M6: =L6/$L$2 -> 0.90204149 | N6: 0 | O6: =N6/$N$2 -> 0 | P6: 84.882636 | Q6: =P6/$P$2 -> 0.74107977
A7: 1.76 | B7: 9.29 | C7: 1 | D7: 1 | E7: 1 | F7: 10 | G7: 1.08 | H7: 5 | I7: =G7*'week8reox ph5&8'!$H7 -> 5.4 | J7: =I7/$I$2 -> 0.57754011 | K7: 2 | L7: 72.940537 | M7: =L7/$L$2 -> 0.77309955 | N7: 0 | O7: =N7/$N$2 -> 0 | P7: 85.075745 | Q7: =P7/$P$2 -> 0.74276574
A8: 2 | B8: 9.29 | C8: 1 | D8: 1 | E8: 1 | F8: 10 | G8: 0.9 | H8: 5 | I8: =G8*'week8reox ph5&8'!$H8 -> 4.5 | J8: =I8/$I$2 -> 0.48128342 | K8: 2 | L8: 85.621158 | M8: =L8/$L$2 -> 0.90750193 | N8: 0 | O8: =N8/$N$2 -> 0 | P8: 84.271794 | Q8: =P8/$P$2 -> 0.73574673
A9: 0 | B9: 9.29 | C9: 1 | D9: 2 | E9: 1 | F9: 10 | H9: 5 | I9: =G9*'week8reox ph5&8'!$H9 -> 0 | K9: 2 | L9: 109.69064 | M9: =L9/$L$9 -> 1 | N9: 104.92673 | O9: =N9/$N$9 -> 1 | P9: 93.533256 | Q9: =P9/$P$9 -> 1
A10: 0.43 | B10: 9.29 | C10: 1 | D10: 2 | E10: 1 | F10: 10 | H10: 5 | I10: =G10*'week8reox ph5&8'!$H10 -> 0 | K10: 2 | L10: 83.897537 | M10: =L10/$L$9 -> 0.76485593 | N10: 5.4638448 | O10: =N10/$N$10 -> 1 | P10: 94.182611 | Q10: =P10/$P$2 -> 0.82227451
A11: 0.66 | B11: 9.29 | C11: 1 | D11: 2 | E11: 1 | F11: 10 | H11: 5 | I11: =G11*'week8reox ph5&8'!$H11 -> 0 | K11: 2 | L11: 92.12731 | M11: =L11/$L$9 -> 0.83988304 | N11: 0 | O11: =N11/$N$10 -> 0 | P11: 97.068755 | Q11: =P11/$P$2 -> 0.84747239
A12: 1 | B12: 9.29 | C12: 1 | D12: 2 | E12: 1 | F12: 10 | H12: 5 | I12: =G12*'week8reox ph5&8'!$H12 -> 0 | K12: 2 | L12: 84.176306 | M12: =L12/$L$9 -> 0.76739733 | N12: 0 | O12: =N12/$N$10 -> 0 | P12: 88.523443 | Q12: =P12/$P$2 -> 0.77286635
A13: 1.33 | B13: 9.29 | C13: 1 | D13: 2 | E13: 1 | F13: 10 | H13: 5 | I13: =G13*'week8reox ph5&8'!$H13 -> 0 | K13: 2 | L13: 69.170964 | M13: =L13/$L$9 -> 0.63060042 | N13: 0 | O13: =N13/$N$10 -> 0 | P13: 96.540329 | Q13: =P13/$P$2 -> 0.8428589
A14: 1.76 | B14: 9.29 | C14: 1 | D14: 2 | E14: 1 | F14: 10 | H14: 5 | I14: =G14*'week8reox ph5&8'!$H14 -> 0 | K14: 2 | L14: 91.6803 | M14: =L14/$L$9 -> 0.83580786 | N14: 0 | O14: =N14/$N$10 -> 0 | P14: 85.295519 | Q14: =P14/$P$2 -> 0.7446845
A15: 2 | B15: 9.29 | C15: 1 | D15: 2 | E15: 1 | F15: 10 | H15: 5 | I15: =G15*'week8reox ph5&8'!$H15 -> 0 | K15: 2 | L15: 62.878325 | M15: =L15/$L$9 -> 0.57323327 | N15: 0 | O15: =N15/$N$10 -> 0 | P15: 86.867061 | Q15: =P15/$P$2 -> 0.75840508
A16: 0 | B16: 9.27 | C16: 2 | D16: 1 | E16: 1 | F16: 10 | G16: 1.77 | H16: 5 | I16: =G16*'week8reox ph5&8'!$H16 -> 8.85 | J16: =I16/$I$16 -> 1 | K16: 2 | L16: 95.401634 | M16: =L16/$L$16 -> 1 | N16: 73.156555 | O16: =N16/$N$16 -> 1 | P16: 96.381155 | Q16: =P16/$P$16 -> 1
A17: 0.43 | B17: 9.27 | C17: 2 | D17: 1 | E17: 1 | F17: 10 | G17: 1.61 | H17: 5 | I17: =G17*'week8reox ph5&8'!$H17 -> 8.05 | J17: =I17/$I$16 -> 0.90960452 | K17: 2 | L17: 94.99529 | M17: =L17/$L$16 -> 0.9957407 | N17: 78.461917 | O17: =N17/$N$16 -> 1.0725207 | P17: 101.9676 | Q17: =P17/$P$16 -> 1.0579621
A18: 0.66 | B18: 9.27 | C18: 2 | D18: 1 | E18: 1 | F18: 10 | G18: 1.46 | H18: 5 | I18: =G18*'week8reox ph5&8'!$H18 -> 7.3 | J18: =I18/$I$16 -> 0.82485876 | K18: 2 | L18: 87.624615 | M18: =L18/$L$16 -> 0.91848128 | N18: 0 | O18: =N18/$N$16 -> 0 | P18: 94.994642 | Q18: =P18/$P$16 -> 0.98561428
A19: 1 | B19: 9.27 | C19: 2 | D19: 1 | E19: 1 | F19: 10 | G19: 1.32 | H19: 5 | I19: =G19*'week8reox ph5&8'!$H19 -> 6.6 | J19: =I19/$I$16 -> 0.74576271 | K19: 2 | L19: 84.262052 | M19: =L19/$L$16 -> 0.88323489 | N19: 0 | O19: =N19/$N$16 -> 0 | P19: 96.331867 | Q19: =P19/$P$16 -> 0.99948862
A20: 1.33 | B20: 9.27 | C20: 2 | D20: 1 | E20: 1 | F20: 10 | G20: 1.17 | H20: 5 | I20: =G20*'week8reox ph5&8'!$H20 -> 5.85 | J20: =I20/$I$16 -> 0.66101695 | K20: 2 | L20: 74.42777 | M20: =L20/$L$16 -> 0.78015194 | N20: 0 | O20: =N20/$N$16 -> 0 | P20: 93.660649 | Q20: =P20/$P$16 -> 0.97177347
A21: 1.76 | B21: 9.27 | C21: 2 | D21: 1 | E21: 1 | F21: 10 | G21: 1.05 | H21: 5 | I21: =G21*'week8reox ph5&8'!$H21 -> 5.25 | J21: =I21/$I$16 -> 0.59322034 | K21: 2 | L21: 78.872081 | M21: =L21/$L$16 -> 0.82673721 | N21: 0 | O21: =N21/$N$16 -> 0 | P21: 89.782293 | Q21: =P21/$P$16 -> 0.93153369
A22: 2 | B22: 9.27 | C22: 2 | D22: 1 | E22: 1 | F22: 10 | G22: 0.87 | H22: 5 | I22: =G22*'week8reox ph5&8'!$H22 -> 4.35 | J22: =I22/$I$16 -> 0.49152542 | K22: 2 | L22: 66.478375 | M22: =L22/$L$16 -> 0.69682637 | N22: 0 | O22: =N22/$N$16 -> 0 | P22: 93.046576 | Q22: =P22/$P$16 -> 0.96540217
A23: 0 | B23: 9.27 | C23: 2 | D23: 2 | E23: 1 | F23: 10 | H23: 5 | I23: =G23*'week8reox ph5&8'!$H23 -> 0 | K23: 2 | L23: 95.230704 | M23: =L23/$L$23 -> 1 | N23: 78.461917 | O23: =N23/$N$23 -> 1 | P23: 102.8265 | Q23: =P23/$P$23 -> 1
A24: 0.43 | B24: 9.27 | C24: 2 | D24: 2 | E24: 1 | F24: 10 | H24: 5 | I24: =G24*'week8reox ph5&8'!$H24 -> 0 | K24: 2 | L24: 81.997059 | M24: =L24/$L$23 -> 0.86103594 | N24: 0 | O24: =N24/$N$23 -> 0 | P24: 98.805935 | Q24: =P24/$P$23 -> 0.96089954
A25: 0.66 | B25: 9.27 | C25: 2 | D25: 2 | E25: 1 | F25: 10 | H25: 5 | I25: =G25*'week8reox ph5&8'!$H25 -> 0 | K25: 2 | L25: 81.477032 | M25: =L25/$L$23 -> 0.85557524 | N25: 0 | O25: =N25/$N$23 -> 0 | P25: 97.784635 | Q25: =P25/$P$23 -> 0.95096727
A26: 1 | B26: 9.27 | C26: 2 | D26: 2 | E26: 1 | F26: 10 | H26: 5 | I26: =G26*'week8reox ph5&8'!$H26 -> 0 | K26: 2 | L26: 82.429251 | M26: =L26/$L$23 -> 0.86557431 | N26: 0 | O26: =N26/$N$23 -> 0 | P26: 99.65271 | Q26: =P26/$P$23 -> 0.96913453
A27: 1.33 | B27: 9.27 | C27: 2 | D27: 2 | E27: 1 | F27: 10 | H27: 5 | I27: =G27*'week8reox ph5&8'!$H27 -> 0 | K27: 2 | L27: 72.451429 | M27: =L27/$L$23 -> 0.76079905 | N27: 0 | O27: =N27/$N$23 -> 0 | P27: 115.48125 | Q27: =P27/$P$23 -> 1.123069
A28: 1.76 | B28: 9.27 | C28: 2 | D28: 2 | E28: 1 | F28: 10 | H28: 5 | I28: =G28*'week8reox ph5&8'!$H28 -> 0 | K28: 2 | L28: 73.71319 | M28: =L28/$L$23 -> 0.77404857 | N28: 0 | O28: =N28/$N$23 -> 0 | P28: 94.720733 | Q28: =P28/$P$23 -> 0.92117046
A29: 2 | B29: 9.27 | C29: 2 | D29: 2 | E29: 1 | F29: 10 | H29: 5 | I29: =G29*'week8reox ph5&8'!$H29 -> 0 | K29: 2 | L29: 67.52818 | M29: =L29/$L$23 -> 0.70910092 | N29: 0 | O29: =N29/$N$23 -> 0 | P29: 89.600495 | Q29: =P29/$P$23 -> 0.87137553
A30: 0 | B30: 5.54 | C30: 1 | D30: 1 | E30: 1 | F30: 10 | G30: 1.69 | H30: 5 | I30: =G30*'week8reox ph5&8'!$H30 -> 8.45 | J30: =I30/$I$30 -> 1 | K30: 2 | L30: 90.048525 | M30: =L30/$L$30 -> 1 | N30: 91.300326 | O30: =N30/$N$30 -> 1 | P30: 106.43014 | Q30: =P30/$P$30 -> 1
A31: 0.43 | B31: 5.54 | C31: 1 | D31: 1 | E31: 1 | F31: 10 | G31: 1.59 | H31: 5 | I31: =G31*'week8reox ph5&8'!$H31 -> 7.95 | J31: =I31/$I$30 -> 0.9408284 | K31: 2 | L31: 60.079864 | M31: =L31/$L$30 -> 0.66719431 | N31: 0 | O31: =N31/$N$30 -> 0 | P31: 72.801555 | Q31: =P31/$P$30 -> 0.68403139
A32: 0.66 | B32: 5.54 | C32: 1 | D32: 1 | E32: 1 | F32: 10 | G32: 1.45 | H32: 5 | I32: =G32*'week8reox ph5&8'!$H32 -> 7.25 | J32: =I32/$I$30 -> 0.85798817 | K32: 2 | L32: 26.777057 | M32: =L32/$L$30 -> 0.29736253 | N32: 0 | O32: =N32/$N$30 -> 0 | P32: 50.475149 | Q32: =P32/$P$30 -> 0.47425617
A33: 1 | B33: 5.54 | C33: 1 | D33: 1 | E33: 1 | F33: 10 | G33: 1.29 | H33: 5 | I33: =G33*'week8reox ph5&8'!$H33 -> 6.45 | J33: =I33/$I$30 -> 0.76331361 | K33: 2 | L33: 14.342791 | M33: =L33/$L$30 -> 0.15927847 | N33: 0 | O33: =N33/$N$30 -> 0 | P33: 33.911874 | Q33: =P33/$P$30 -> 0.31863037
A34: 1.33 | B34: 5.54 | C34: 1 | D34: 1 | E34: 1 | F34: 10 | G34: 1.17 | H34: 5 | I34: =G34*'week8reox ph5&8'!$H34 -> 5.85 | J34: =I34/$I$30 -> 0.69230769 | K34: 2 | L34: 7.0846349 | M34: =L34/$L$30 -> 0.078675747 | N34: 0 | O34: =N34/$N$30 -> 0 | P34: 17.392768 | Q34: =P34/$P$30 -> 0.16341958
A35: 1.76 | B35: 5.54 | C35: 1 | D35: 1 | E35: 1 | F35: 10 | G35: 0.99 | H35: 5 | I35: =G35*'week8reox ph5&8'!$H35 -> 4.95 | J35: =I35/$I$30 -> 0.58579882 | K35: 2 | L35: 2.4018199 | M35: =L35/$L$30 -> 0.026672507 | N35: 0 | O35: =N35/$N$30 -> 0 | P35: 7.5086151 | Q35: =P35/$P$30 -> 0.070549707
A36: 2 | B36: 5.54 | C36: 1 | D36: 1 | E36: 1 | F36: 10 | G36: 0.85 | H36: 5 | I36: =G36*'week8reox ph5&8'!$H36 -> 4.25 | J36: =I36/$I$30 -> 0.50295858 | K36: 2 | L36: 0.6056712 | M36: =L36/$L$30 -> 0.0067260535 | N36: 0 | O36: =N36/$N$30 -> 0 | P36: 4.309779 | Q36: =P36/$P$30 -> 0.040493971
A37: 0 | B37: 5.54 | C37: 1 | D37: 2 | E37: 1 | F37: 10 | H37: 5 | I37: =G37*'week8reox ph5&8'!$H37 -> 0 | K37: 2 | L37: 103.29134 | M37: =L37/$L$37 -> 1 | N37: 84.423797 | O37: =N37/$N$37 -> 1 | P37: 106.55618 | Q37: =P37/$P$37 -> 1
A38: 0.43 | B38: 5.54 | C38: 1 | D38: 2 | E38: 1 | F38: 10 | H38: 5 | I38: =G38*'week8reox ph5&8'!$H38 -> 0 | K38: 2 | L38: 65.551226 | M38: =L38/$L$37 -> 0.63462461 | N38: 0 | O38: =N38/$N$37 -> 0 | P38: 71.105582 | Q38: =P38/$P$37 -> 0.66730601
A39: 0.66 | B39: 5.54 | C39: 1 | D39: 2 | E39: 1 | F39: 10 | H39: 5 | I39: =G39*'week8reox ph5&8'!$H39 -> 0 | K39: 2 | L39: 30.760947 | M39: =L39/$L$37 -> 0.29780761 | N39: 0 | O39: =N39/$N$37 -> 0 | P39: 49.091869 | Q39: =P39/$P$37 -> 0.46071346
A40: 1 | B40: 5.54 | C40: 1 | D40: 2 | E40: 1 | F40: 10 | H40: 5 | I40: =G40*'week8reox ph5&8'!$H40 -> 0 | K40: 2 | L40: 11.614451 | M40: =L40/$L$37 -> 0.11244361 | N40: 0 | O40: =N40/$N$37 -> 0 | P40: 27.531439 | Q40: =P40/$P$37 -> 0.25837485
...

Sheet week8reox ph7
A1: time(minute) | B1: pH | C1: experiment replicate | D1: sample replicate | E1: UV | F1: Nominal Cl2(0) | G1: Cl2free (mgCl2/L) diluted x5 | H1: DPD dilution factor | I1: Cl2free (mgCl2/L) | J1: Cl2free C/C0 | K1: Phosphate buffer (mM) | L1: dioxane (microgram/L) | M1: dioxane C/C0 | N1: caffeine (microgam/L) | O1: caffeine C/C0 | P1: sucralose (microgram/L | Q1: sucralose C/C0
A2: 0 | B2: 7.65 | C2: 1 | D2: 1 | E2: 1 | F2: 10 | G2: 1.68 | H2: 5 | I2: =G2*'week8reox ph7'!$H2 -> 8.4 | J2: =I2/$I$2 -> 1 | K2: 2 | L2: 75.09 | M2: =L2/$L$2 -> 1 | N2: 81.68 | O2: =N2/$N$2 -> 1 | P2: 79.44 | Q2: =P2/$P$2 -> 1
A3: 0.43 | B3: 7.65 | C3: 1 | D3: 1 | E3: 1 | F3: 10 | G3: 1.53 | H3: 5 | I3: =G3*'week8reox ph7'!$H3 -> 7.65 | J3: =I3/$I$2 -> 0.91071429 | K3: 2 | L3: 61.92 | M3: =L3/$L$2 -> 0.82461047 | N3: 1.96 | O3: =N3/$N$2 -> 0.023996082 | P3: 73.51 | Q3: =P3/$P$2 -> 0.92535247
A4: 0.66 | B4: 7.65 | C4: 1 | D4: 1 | E4: 1 | F4: 10 | G4: 1.34 | H4: 5 | I4: =G4*'week8reox ph7'!$H4 -> 6.7 | J4: =I4/$I$2 -> 0.79761905 | K4: 2 | L4: 57.2 | M4: =L4/$L$2 -> 0.76175256 | N4: 0 | O4: =N4/$N$2 -> 0 | P4: 77.45 | Q4: =P4/$P$2 -> 0.97494965
A5: 1 | B5: 7.65 | C5: 1 | D5: 1 | E5: 1 | F5: 10 | G5: 1.21 | H5: 5 | I5: =G5*'week8reox ph7'!$H5 -> 6.05 | J5: =I5/$I$2 -> 0.7202381 | K5: 2 | L5: 53.78 | M5: =L5/$L$2 -> 0.71620722 | N5: 0 | O5: =N5/$N$2 -> 0 | P5: 74.54 | Q5: =P5/$P$2 -> 0.93831823
A6: 1.33 | B6: 7.65 | C6: 1 | D6: 1 | E6: 1 | F6: 10 | G6: 1.09 | H6: 5 | I6: =G6*'week8reox ph7'!$H6 -> 5.45 | J6: =I6/$I$2 -> 0.64880952 | K6: 2 | L6: 44.8 | M6: =L6/$L$2 -> 0.59661739 | N6: 0 | O6: =N6/$N$2 -> 0 | P6: 71.87 | Q6: =P6/$P$2 -> 0.90470796
A7: 1.76 | B7: 7.65 | C7: 1 | D7: 1 | E7: 1 | F7: 10 | G7: 0.98 | H7: 5 | I7: =G7*'week8reox ph7'!$H7 -> 4.9 | J7: =I7/$I$2 -> 0.58333333 | K7: 2 | L7: 55.02 | M7: =L7/$L$2 -> 0.73272074 | N7: 0 | O7: =N7/$N$2 -> 0 | P7: 68.6 | Q7: =P7/$P$2 -> 0.86354481
A8: 2 | B8: 7.65 | C8: 1 | D8: 1 | E8: 1 | F8: 10 | G8: 0.84 | H8: 5 | I8: =G8*'week8reox ph7'!$H8 -> 4.2 | J8: =I8/$I$2 -> 0.5 | K8: 2 | L8: 55.27 | M8: =L8/$L$2 -> 0.73605007 | N8: 0 | O8: =N8/$N$2 -> 0 | P8: 66.34 | Q8: =P8/$P$2 -> 0.83509567
A9: 0 | B9: 7.65 | C9: 1 | D9: 2 | E9: 1 | F9: 10 | H9: 5 | I9: =G9*'week8reox ph7'!$H9 -> 0 | K9: 2 | L9: 67.76 | M9: =L9/$L$9 -> 1 | N9: 67.81 | O9: =N9/$N$9 -> 1 | P9: 80.11 | Q9: =P9/$P$9 -> 1
A10: 0.43 | B10: 7.65 | C10: 1 | D10: 2 | E10: 1 | F10: 10 | H10: 5 | I10: =G10*'week8reox ph7'!$H10 -> 0 | K10: 2 | L10: 56.2 | M10: =L10/$L$9 -> 0.82939787 | N10: 2.19 | O10: =N10/$N$10 -> 1 | P10: 78.74 | Q10: =P10/$P$2 -> 0.99118832
A11: 0.66 | B11: 7.65 | C11: 1 | D11: 2 | E11: 1 | F11: 10 | H11: 5 | I11: =G11*'week8reox ph7'!$H11 -> 0 | K11: 2 | M11: =L11/$L$9 -> 0 | N11: 0 | O11: =N11/$N$10 -> 0 | P11: 79.03 | Q11: =P11/$P$2 -> 0.99483887
A12: 1 | B12: 7.65 | C12: 1 | D12: 2 | E12: 1 | F12: 10 | H12: 5 | I12: =G12*'week8reox ph7'!$H12 -> 0 | K12: 2 | L12: 52.59 | M12: =L12/$L$9 -> 0.77612161 | N12: 0 | O12: =N12/$N$10 -> 0 | P12: 78.41 | Q12: =P12/$P$2 -> 0.98703424
A13: 1.33 | B13: 7.65 | C13: 1 | D13: 2 | E13: 1 | F13: 10 | H13: 5 | I13: =G13*'week8reox ph7'!$H13 -> 0 | K13: 2 | L13: 44.78 | M13: =L13/$L$9 -> 0.66086187 | N13: 0 | O13: =N13/$N$10 -> 0 | P13: 78.41 | Q13: =P13/$P$2 -> 0.98703424
A14: 1.76 | B14: 7.65 | C14: 1 | D14: 2 | E14: 1 | F14: 10 | H14: 5 | I14: =G14*'week8reox ph7'!$H14 -> 0 | K14: 2 | L14: 55.86 | M14: =L14/$L$9 -> 0.82438017 | N14: 0 | O14: =N14/$N$10 -> 0 | P14: 64.23 | Q14: =P14/$P$2 -> 0.80853474
A15: 2 | B15: 7.65 | C15: 1 | D15: 2 | E15: 1 | F15: 10 | H15: 5 | I15: =G15*'week8reox ph7'!$H15 -> 0 | K15: 2 | L15: 45.35 | M15: =L15/$L$9 -> 0.66927391 | N15: 0 | O15: =N15/$N$10 -> 0 | P15: 70.31 | Q15: =P15/$P$2 -> 0.88507049
A16: 0 | B16: 7.65 | C16: 2 | D16: 1 | E16: 1 | F16: 10 | G16: 1.73 | H16: 5 | I16: =G16*'week8reox ph7'!$H16 -> 8.65 | J16: =I16/$I$16 -> 1 | K16: 2 | L16: 103.11 | M16: =L16/$L$16 -> 1 | N16: 96.71 | O16: =N16/$N$16 -> 1 | P16: 87.3 | Q16: =P16/$P$16 -> 1
A17: 0.43 | B17: 7.65 | C17: 2 | D17: 1 | E17: 1 | F17: 10 | G17: 1.53 | H17: 5 | I17: =G17*'week8reox ph7'!$H17 -> 7.65 | J17: =I17/$I$16 -> 0.88439306 | K17: 2 | L17: 85.84 | M17: =L17/$L$16 -> 0.83250897 | N17: 2.85 | O17: =N17/$N$16 -> 0.029469548 | P17: 79.34 | Q17: =P17/$P$16 -> 0.90882016
A18: 0.66 | B18: 7.65 | C18: 2 | D18: 1 | E18: 1 | F18: 10 | G18: 1.41 | H18: 5 | I18: =G18*'week8reox ph7'!$H18 -> 7.05 | J18: =I18/$I$16 -> 0.8150289 | K18: 2 | L18: 98.1 | M18: =L18/$L$16 -> 0.95141111 | N18: 0 | O18: =N18/$N$16 -> 0 | P18: 79.95 | Q18: =P18/$P$16 -> 0.91580756
A19: 1 | B19: 7.65 | C19: 2 | D19: 1 | E19: 1 | F19: 10 | G19: 1.24 | H19: 5 | I19: =G19*'week8reox ph7'!$H19 -> 6.2 | J19: =I19/$I$16 -> 0.71676301 | K19: 2 | L19: 81.66 | M19: =L19/$L$16 -> 0.79196974 | N19: 0 | O19: =N19/$N$16 -> 0 | P19: 91.75 | Q19: =P19/$P$16 -> 1.0509737
A20: 1.33 | B20: 7.65 | C20: 2 | D20: 1 | E20: 1 | F20: 10 | G20: 1.16 | H20: 5 | I20: =G20*'week8reox ph7'!$H20 -> 5.8 | J20: =I20/$I$16 -> 0.67052023 | K20: 2 | L20: 87.12 | M20: =L20/$L$16 -> 0.8449229 | N20: 0 | O20: =N20/$N$16 -> 0 | P20: 88.54 | Q20: =P20/$P$16 -> 1.0142039
A21: 1.76 | B21: 7.65 | C21: 2 | D21: 1 | E21: 1 | F21: 10 | G21: 0.97 | H21: 5 | I21: =G21*'week8reox ph7'!$H21 -> 4.85 | J21: =I21/$I$16 -> 0.56069364 | K21: 2 | L21: 80.68 | M21: =L21/$L$16 -> 0.78246533 | N21: 0 | O21: =N21/$N$16 -> 0 | P21: 78.75 | Q21: =P21/$P$16 -> 0.90206186
A22: 2 | B22: 7.65 | C22: 2 | D22: 1 | E22: 1 | F22: 10 | G22: 0.87 | H22: 5 | I22: =G22*'week8reox ph7'!$H22 -> 4.35 | J22: =I22/$I$16 -> 0.50289017 | K22: 2 | L22: 72.2 | M22: =L22/$L$16 -> 0.70022306 | N22: 0 | O22: =N22/$N$16 -> 0 | P22: 77.54 | Q22: =P22/$P$16 -> 0.8882016
A23: 0 | B23: 7.65 | C23: 2 | D23: 2 | E23: 1 | F23: 10 | H23: 5 | I23: =G23*'week8reox ph7'!$H23 -> 0 | K23: 2 | L23: 103.05 | M23: =L23/$L$23 -> 1 | N23: 91.3 | O23: =N23/$N$23 -> 1 | P23: 89.41 | Q23: =P23/$P$23 -> 1
A24: 0.43 | B24: 7.65 | C24: 2 | D24: 2 | E24: 1 | F24: 10 | H24: 5 | I24: =G24*'week8reox ph7'!$H24 -> 0 | K24: 2 | L24: 95.87 | M24: =L24/$L$23 -> 0.93032508 | N24: 2.89 | O24: =N24/$N$23 -> 0.031653888 | P24: 80.98 | Q24: =P24/$P$23 -> 0.90571524
A25: 0.66 | B25: 7.65 | C25: 2 | D25: 2 | E25: 1 | F25: 10 | H25: 5 | I25: =G25*'week8reox ph7'!$H25 -> 0 | K25: 2 | L25: 110.51 | M25: =L25/$L$23 -> 1.072392 | N25: 0 | O25: =N25/$N$23 -> 0 | P25: 80.54 | Q25: =P25/$P$23 -> 0.90079409
A26: 1 | B26: 7.65 | C26: 2 | D26: 2 | E26: 1 | F26: 10 | H26: 5 | I26: =G26*'week8reox ph7'!$H26 -> 0 | K26: 2 | L26: 84.86 | M26: =L26/$L$23 -> 0.82348375 | N26: 0 | O26: =N26/$N$23 -> 0 | P26: 90.7 | Q26: =P26/$P$23 -> 1.0144279
A27: 1.33 | B27: 7.65 | C27: 2 | D27: 2 | E27: 1 | F27: 10 | H27: 5 | I27: =G27*'week8reox ph7'!$H27 -> 0 | K27: 2 | L27: 76.36 | M27: =L27/$L$23 -> 0.74099951 | N27: 0 | O27: =N27/$N$23 -> 0 | P27: 88.73 | Q27: =P27/$P$23 -> 0.99239459
A28: 1.76 | B28: 7.65 | C28: 2 | D28: 2 | E28: 1 | F28: 10 | H28: 5 | I28: =G28*'week8reox ph7'!$H28 -> 0 | K28: 2 | L28: 78.41 | M28: =L28/$L$23 -> 0.76089277 | N28: 0 | O28: =N28/$N$23 -> 0 | P28: 79.63 | Q28: =P28/$P$23 -> 0.89061626
A29: 2 | B29: 7.65 | C29: 2 | D29: 2 | E29: 1 | F29: 10 | H29: 5 | I29: =G29*'week8reox ph7'!$H29 -> 0 | K29: 2 | L29: 76.92 | M29: =L29/$L$23 -> 0.74643377 | N29: 0 | O29: =N29/$N$23 -> 0 | P29: 79.14 | Q29: =P29/$P$23 -> 0.88513589
A30: 0 | B30: 7.62 | C30: 2 | D30: 1 | E30: 1 | F30: 2 | G30: 1.64 | H30: 1 | I30: =G30*'week8reox ph7'!$H30 -> 1.64 | J30: =I30/$I$30 -> 1 | K30: 2 | N30: 104.86 | O30: =N30/$N$30 -> 1 | P30: 99.85 | Q30: =P30/$P$30 -> 1
A31: 0.43 | B31: 7.62 | C31: 2 | D31: 1 | E31: 1 | F31: 2 | G31: 1.4 | H31: 1 | I31: =G31*'week8reox ph7'!$H31 -> 1.4 | J31: =I31/$I$30 -> 0.85365854 | K31: 2 | N31: 27.91 | O31: =N31/$N$30 -> 0.26616441 | P31: 95.6 | Q31: =P31/$P$30 -> 0.95743615
A32: 0.66 | B32: 7.62 | C32: 2 | D32: 1 | E32: 1 | F32: 2 | G32: 1.16 | H32: 1 | I32: =G32*'week8reox ph7'!$H32 -> 1.16 | J32: =I32/$I$30 -> 0.70731707 | K32: 2 | N32: 5.95 | O32: =N32/$N$30 -> 0.056742323 | P32: 86.59 | Q32: =P32/$P$30 -> 0.8672008
A33: 1 | B33: 7.62 | C33: 2 | D33: 1 | E33: 1 | F33: 2 | G33: 0.97 | H33: 1 | I33: =G33*'week8reox ph7'!$H33 -> 0.97 | J33: =I33/$I$30 -> 0.59146341 | K33: 2 | N33: 1.06 | O33: =N33/$N$30 -> 0.010108716 | P33: 88.46 | Q33: =P33/$P$30 -> 0.88592889
A34: 1.33 | B34: 7.62 | C34: 2 | D34: 1 | E34: 1 | F34: 2 | G34: 0.81 | H34: 1 | I34: =G34*'week8reox ph7'!$H34 -> 0.81 | J34: =I34/$I$30 -> 0.49390244 | K34: 2 | N34: 0.14 | O34: =N34/$N$30 -> 0.0013351135 | P34: 80.82 | Q34: =P34/$P$30 -> 0.80941412
A35: 1.76 | B35: 7.62 | C35: 2 | D35: 1 | E35: 1 | F35: 2 | G35: 0.62 | H35: 1 | I35: =G35*'week8reox ph7'!$H35 -> 0.62 | J35: =I35/$I$30 -> 0.37804878 | K35: 2 | N35: 0 | O35: =N35/$N$30 -> 0 | P35: 76.07 | Q35: =P35/$P$30 -> 0.76184276
A36: 2 | B36: 7.62 | C36: 2 | D36: 1 | E36: 1 | F36: 2 | G36: 0.51 | H36: 1 | I36: =G36*'week8reox ph7'!$H36 -> 0.51 | J36: =I36/$I$30 -> 0.31097561 | K36: 2 | N36: 0 | O36: =N36/$N$30 -> 0 | P36: 66.81 | Q36: =P36/$P$30 -> 0.66910366
A37: 0 | B37: 7.62 | C37: 2 | D37: 2 | E37: 1 | F37: 2 | H37: 1 | I37: =G37*'week8reox ph7'!$H37 -> 0 | K37: 2 | N37: 106.5 | O37: =N37/$N$37 -> 1 | P37: 100.67 | Q37: =P37/$P$37 -> 1
A38: 0.43 | B38: 7.62 | C38: 2 | D38: 2 | E38: 1 | F38: 2 | H38: 1 | I38: =G38*'week8reox ph7'!$H38 -> 0 | K38: 2 | N38: 27.33 | O38: =N38/$N$37 -> 0.25661972 | P38: 93.81 | Q38: =P38/$P$37 -> 0.93185656
A39: 0.66 | B39: 7.62 | C39: 2 | D39: 2 | E39: 1 | F39: 2 | H39: 1 | I39: =G39*'week8reox ph7'!$H39 -> 0 | K39: 2 | N39: 5.69 | O39: =N39/$N$37 -> 0.05342723 | P39: 88.92 | Q39: =P39/$P$37 -> 0.88328201
A40: 1 | B40: 7.62 | C40: 2 | D40: 2 | E40: 1 | F40: 2 | H40: 1 | I40: =G40*'week8reox ph7'!$H40 -> 0 | K40: 2 | N40: 0.93 | O40: =N40/$N$37 -> 0.0087323944 | P40: 80.82 | Q40: =P40/$P$37 -> 0.8028211
...
